Workbook

Sheet 00_PORTADA
A1: HODOM - LIBRO OPERATIVO IDEAL
A3: Para que sirve
A4: Base nueva para reemplazar la planilla antigua sin heredar su desorden ni sus errores.
A6: Que trae
A7: 1. Parametros generales.
A8: 2. Diccionario de indicadores.
A9: 3. Tracker de migracion.
A10: 4. Resumen global.
A11: 5. Una hoja mensual estandar por cada mes.
A13: Como esta pensado
A14: Las celdas amarillas son para cargar datos.
A15: Las verdes calculan solas.
... A20: No escribir encima de formulas. Si algo no cuadra, se corrige en la fila diaria, no en el resumen.

Sheet 01_PARAMETROS
A1: PARAMETROS GENERALES
A3: Servicio | B3: HODOM | D3: Criterios fijos
A4: Codigo | D4: Pacientes atendidos = censo inicial + ingresos
A5: Camas base por dia | B5: 16 | D5: Indice ocupacional = dias cama ocupadas / dias cama disponibles
A6: Responsable | D6: Promedio dia de estada = dias estada total / total egresos
A7: Centro / unidad | D7: Si no hay desglose, se puede usar total informado del dia
A8: Notas generales

Sheet 02_DICCIONARIO
A1: DICCIONARIO DE CAMPOS E INDICADORES
A3: Elemento | B3: Tipo | C3: Que significa | D3: Como se obtiene
A4: Existencia dia anterior | B4: Dato / formula | C4: Pacientes con que parte el dia | D4: Dia 1 manual, resto arrastra desde camas ocupadas del dia previo
A5: Total ingresos | B5: Formula | C5: Todos los ingresos del dia | D5: Si hay desglose usa la suma; si no, usa el total informado
A6: Total ingresos informado | B6: Dato opcional | C6: Total del dia cuando no existe desglose | D6: Se carga solo si no hay detalle por tipo
A7: Total egresos | B7: Formula | C7: Todos los egresos del dia | D7: Si hay desglose usa la suma; si no, usa el total informado
A8: Total egresos informado | B8: Dato opcional | C8: Total del dia cuando no existe desglose | D8: Se carga solo si no hay detalle por tipo
A9: Dias cama ocupadas | B9: Formula | C9: Censo final del dia | D9: Existencia inicial + ingresos - egresos
A10: Pacientes atendidos del mes | B10: Formula | C10: Personas que pasaron por el servicio en el mes | D10: Censo inicial + ingresos totales
A11: Dias personas atendidas | B11: Formula | C11: Acumulado de estada del mes | D11: Suma de dias estada total
A12: Indice ocupacional | B12: Formula | C12: Nivel de ocupacion del mes | D12: Dias cama ocupadas / dias cama disponibles
A13: Promedio dia de estada | B13: Formula | C13: Promedio de permanencia | D13: Dias estada total / total egresos
A14: Balance del mes | B14: Control | C14: Chequea consistencia del mes | D14: Censo inicial + ingresos - egresos - censo final

Sheet 03_MIGRACION
A1: TRACKER DE MIGRACION
A3: Mes | B3: Estado | C3: Fuente original | D3: Migrado por | E3: Validado | F3: Notas
A4: DICIEMBRE 2024 | B4: Pendiente
A5: ENERO 2025 | B5: Pendiente
A6: FEBRERO 2025 | B6: Pendiente
A7: MARZO 2025 | B7: Pendiente
A8: ABRIL 2025 | B8: Pendiente
A9: MAYO 2025 | B9: Pendiente
A10: JUNIO 2025 | B10: Pendiente
A11: JULIO 2025 | B11: Pendiente
A12: AGOSTO 2025 | B12: Pendiente
A13: SEPTIEMBRE 2025 | B13: Pendiente
A14: OCTUBRE 2025 | B14: Pendiente
A15: NOVIEMBRE 2025 | B15: Pendiente
... A18: FEBRERO 2026 | B18: Pendiente

Sheet DICIEMBRE 2024
A1: HODOM - DICIEMBRE 2024
A2: Servicio | B2: =01_PARAMETROS!B3 | C2: Codigo | D2: =01_PARAMETROS!B4 | E2: Mes | F2: DICIEMBRE | G2: Ano | H2: 2024 | I2: Camas base | J2: =01_PARAMETROS!B5 | K2: Dias del mes | L2: 31
A6: Fecha | B6: Dia | C6: Existencia inicial | D6: Ing. urgencia | E6: Ing. hospitalizacion | F6: Ing. ambulatorio | G6: Ing. ley urgencia | H6: Ing. UGCC | I6: Ing. traslado | J6: Total ingresos | K6: Total ingresos informado | L6: Alta hogar / otro hosp. | M6: Traslado a otro servicio | N6: Fallecidos | O6: Total egresos | P6: Total egresos informado | Q6: Ingr.-egr. mismo dia | R6: Camas disponibles | S6: Camas ocupadas | T6: Dias estada total | U6: Dias estada benef. | V6: Observaciones | W6: Estado dia | X6: Check camas | Y6: Check balance | Z6: Check faltantes
A7: =DATE(2024,12,1) | B7: 1 | J7: =IF(COUNTA(D7:I7)>0,SUM(D7:I7),IF(K7="", "", K7)) | O7: =IF(COUNTA(L7:N7)>0,SUM(L7:N7),IF(P7="", "", P7)) | S7: =IF(OR(C7="",J7="",O7=""),"",C7+J7-O7) | W7: =IF(Z7=1,"FALTAN DATOS",IF(S7<0,"OCUPACION NEGATIVA",IF(X7=1,"SOBREOCUPACION",IF(Y7<>0,"BALANCE RARO","OK")))) | X7: =IF(AND(R7<>"",S7>R7),1,0) | Y7: =IF(OR(C7="",J7="",O7="",S7=""),"",C7+J7-O7-S7) | Z7: =IF(OR(R7="",A7="",B7="",C7="",J7="",O7=""),1,0)
A8: =DATE(2024,12,2) | B8: 2 | C8: =Q7 | J8: =IF(COUNTA(D8:I8)>0,SUM(D8:I8),IF(K8="", "", K8)) | O8: =IF(COUNTA(L8:N8)>0,SUM(L8:N8),IF(P8="", "", P8)) | S8: =IF(OR(C8="",J8="",O8=""),"",C8+J8-O8) | W8: =IF(Z8=1,"FALTAN DATOS",IF(S8<0,"OCUPACION NEGATIVA",IF(X8=1,"SOBREOCUPACION",IF(Y8<>0,"BALANCE RARO","OK")))) | X8: =IF(AND(R8<>"",S8>R8),1,0) | Y8: =IF(OR(C8="",J8="",O8="",S8=""),"",C8+J8-O8-S8) | Z8: =IF(OR(R8="",A8="",B8="",C8="",J8="",O8=""),1,0)
A9: =DATE(2024,12,3) | B9: 3 | C9: =Q8 | J9: =IF(COUNTA(D9:I9)>0,SUM(D9:I9),IF(K9="", "", K9)) | O9: =IF(COUNTA(L9:N9)>0,SUM(L9:N9),IF(P9="", "", P9)) | S9: =IF(OR(C9="",J9="",O9=""),"",C9+J9-O9) | W9: =IF(Z9=1,"FALTAN DATOS",IF(S9<0,"OCUPACION NEGATIVA",IF(X9=1,"SOBREOCUPACION",IF(Y9<>0,"BALANCE RARO","OK")))) | X9: =IF(AND(R9<>"",S9>R9),1,0) | Y9: =IF(OR(C9="",J9="",O9="",S9=""),"",C9+J9-O9-S9) | Z9: =IF(OR(R9="",A9="",B9="",C9="",J9="",O9=""),1,0)
A10: =DATE(2024,12,4) | B10: 4 | C10: =Q9 | J10: =IF(COUNTA(D10:I10)>0,SUM(D10:I10),IF(K10="", "", K10)) | O10: =IF(COUNTA(L10:N10)>0,SUM(L10:N10),IF(P10="", "", P10)) | S10: =IF(OR(C10="",J10="",O10=""),"",C10+J10-O10) | W10: =IF(Z10=1,"FALTAN DATOS",IF(S10<0,"OCUPACION NEGATIVA",IF(X10=1,"SOBREOCUPACION",IF(Y10<>0,"BALANCE RARO","OK")))) | X10: =IF(AND(R10<>"",S10>R10),1,0) | Y10: =IF(OR(C10="",J10="",O10="",S10=""),"",C10+J10-O10-S10) | Z10: =IF(OR(R10="",A10="",B10="",C10="",J10="",O10=""),1,0)
A11: =DATE(2024,12,5) | B11: 5 | C11: =Q10 | J11: =IF(COUNTA(D11:I11)>0,SUM(D11:I11),IF(K11="", "", K11)) | O11: =IF(COUNTA(L11:N11)>0,SUM(L11:N11),IF(P11="", "", P11)) | S11: =IF(OR(C11="",J11="",O11=""),"",C11+J11-O11) | W11: =IF(Z11=1,"FALTAN DATOS",IF(S11<0,"OCUPACION NEGATIVA",IF(X11=1,"SOBREOCUPACION",IF(Y11<>0,"BALANCE RARO","OK")))) | X11: =IF(AND(R11<>"",S11>R11),1,0) | Y11: =IF(OR(C11="",J11="",O11="",S11=""),"",C11+J11-O11-S11) | Z11: =IF(OR(R11="",A11="",B11="",C11="",J11="",O11=""),1,0)
A12: =DATE(2024,12,6) | B12: 6 | C12: =Q11 | J12: =IF(COUNTA(D12:I12)>0,SUM(D12:I12),IF(K12="", "", K12)) | O12: =IF(COUNTA(L12:N12)>0,SUM(L12:N12),IF(P12="", "", P12)) | S12: =IF(OR(C12="",J12="",O12=""),"",C12+J12-O12) | W12: =IF(Z12=1,"FALTAN DATOS",IF(S12<0,"OCUPACION NEGATIVA",IF(X12=1,"SOBREOCUPACION",IF(Y12<>0,"BALANCE RARO","OK")))) | X12: =IF(AND(R12<>"",S12>R12),1,0) | Y12: =IF(OR(C12="",J12="",O12="",S12=""),"",C12+J12-O12-S12) | Z12: =IF(OR(R12="",A12="",B12="",C12="",J12="",O12=""),1,0)
A13: =DATE(2024,12,7) | B13: 7 | C13: =Q12 | J13: =IF(COUNTA(D13:I13)>0,SUM(D13:I13),IF(K13="", "", K13)) | O13: =IF(COUNTA(L13:N13)>0,SUM(L13:N13),IF(P13="", "", P13)) | S13: =IF(OR(C13="",J13="",O13=""),"",C13+J13-O13) | W13: =IF(Z13=1,"FALTAN DATOS",IF(S13<0,"OCUPACION NEGATIVA",IF(X13=1,"SOBREOCUPACION",IF(Y13<>0,"BALANCE RARO","OK")))) | X13: =IF(AND(R13<>"",S13>R13),1,0) | Y13: =IF(OR(C13="",J13="",O13="",S13=""),"",C13+J13-O13-S13) | Z13: =IF(OR(R13="",A13="",B13="",C13="",J13="",O13=""),1,0)
A14: =DATE(2024,12,8) | B14: 8 | C14: =Q13 | J14: =IF(COUNTA(D14:I14)>0,SUM(D14:I14),IF(K14="", "", K14)) | O14: =IF(COUNTA(L14:N14)>0,SUM(L14:N14),IF(P14="", "", P14)) | S14: =IF(OR(C14="",J14="",O14=""),"",C14+J14-O14) | W14: =IF(Z14=1,"FALTAN DATOS",IF(S14<0,"OCUPACION NEGATIVA",IF(X14=1,"SOBREOCUPACION",IF(Y14<>0,"BALANCE RARO","OK")))) | X14: =IF(AND(R14<>"",S14>R14),1,0) | Y14: =IF(OR(C14="",J14="",O14="",S14=""),"",C14+J14-O14-S14) | Z14: =IF(OR(R14="",A14="",B14="",C14="",J14="",O14=""),1,0)
A15: =DATE(2024,12,9) | B15: 9 | C15: =Q14 | J15: =IF(COUNTA(D15:I15)>0,SUM(D15:I15),IF(K15="", "", K15)) | O15: =IF(COUNTA(L15:N15)>0,SUM(L15:N15),IF(P15="", "", P15)) | S15: =IF(OR(C15="",J15="",O15=""),"",C15+J15-O15) | W15: =IF(Z15=1,"FALTAN DATOS",IF(S15<0,"OCUPACION NEGATIVA",IF(X15=1,"SOBREOCUPACION",IF(Y15<>0,"BALANCE RARO","OK")))) | X15: =IF(AND(R15<>"",S15>R15),1,0) | Y15: =IF(OR(C15="",J15="",O15="",S15=""),"",C15+J15-O15-S15) | Z15: =IF(OR(R15="",A15="",B15="",C15="",J15="",O15=""),1,0)
A16: =DATE(2024,12,10) | B16: 10 | C16: =Q15 | J16: =IF(COUNTA(D16:I16)>0,SUM(D16:I16),IF(K16="", "", K16)) | O16: =IF(COUNTA(L16:N16)>0,SUM(L16:N16),IF(P16="", "", P16)) | S16: =IF(OR(C16="",J16="",O16=""),"",C16+J16-O16) | W16: =IF(Z16=1,"FALTAN DATOS",IF(S16<0,"OCUPACION NEGATIVA",IF(X16=1,"SOBREOCUPACION",IF(Y16<>0,"BALANCE RARO","OK")))) | X16: =IF(AND(R16<>"",S16>R16),1,0) | Y16: =IF(OR(C16="",J16="",O16="",S16=""),"",C16+J16-O16-S16) | Z16: =IF(OR(R16="",A16="",B16="",C16="",J16="",O16=""),1,0)
A17: =DATE(2024,12,11) | B17: 11 | C17: =Q16 | J17: =IF(COUNTA(D17:I17)>0,SUM(D17:I17),IF(K17="", "", K17)) | O17: =IF(COUNTA(L17:N17)>0,SUM(L17:N17),IF(P17="", "", P17)) | S17: =IF(OR(C17="",J17="",O17=""),"",C17+J17-O17) | W17: =IF(Z17=1,"FALTAN DATOS",IF(S17<0,"OCUPACION NEGATIVA",IF(X17=1,"SOBREOCUPACION",IF(Y17<>0,"BALANCE RARO","OK")))) | X17: =IF(AND(R17<>"",S17>R17),1,0) | Y17: =IF(OR(C17="",J17="",O17="",S17=""),"",C17+J17-O17-S17) | Z17: =IF(OR(R17="",A17="",B17="",C17="",J17="",O17=""),1,0)
A18: =DATE(2024,12,12) | B18: 12 | C18: =Q17 | J18: =IF(COUNTA(D18:I18)>0,SUM(D18:I18),IF(K18="", "", K18)) | O18: =IF(COUNTA(L18:N18)>0,SUM(L18:N18),IF(P18="", "", P18)) | S18: =IF(OR(C18="",J18="",O18=""),"",C18+J18-O18) | W18: =IF(Z18=1,"FALTAN DATOS",IF(S18<0,"OCUPACION NEGATIVA",IF(X18=1,"SOBREOCUPACION",IF(Y18<>0,"BALANCE RARO","OK")))) | X18: =IF(AND(R18<>"",S18>R18),1,0) | Y18: =IF(OR(C18="",J18="",O18="",S18=""),"",C18+J18-O18-S18) | Z18: =IF(OR(R18="",A18="",B18="",C18="",J18="",O18=""),1,0)
A19: =DATE(2024,12,13) | B19: 13 | C19: =Q18 | J19: =IF(COUNTA(D19:I19)>0,SUM(D19:I19),IF(K19="", "", K19)) | O19: =IF(COUNTA(L19:N19)>0,SUM(L19:N19),IF(P19="", "", P19)) | S19: =IF(OR(C19="",J19="",O19=""),"",C19+J19-O19) | W19: =IF(Z19=1,"FALTAN DATOS",IF(S19<0,"OCUPACION NEGATIVA",IF(X19=1,"SOBREOCUPACION",IF(Y19<>0,"BALANCE RARO","OK")))) | X19: =IF(AND(R19<>"",S19>R19),1,0) | Y19: =IF(OR(C19="",J19="",O19="",S19=""),"",C19+J19-O19-S19) | Z19: =IF(OR(R19="",A19="",B19="",C19="",J19="",O19=""),1,0)
A20: =DATE(2024,12,14) | B20: 14 | C20: =Q19 | J20: =IF(COUNTA(D20:I20)>0,SUM(D20:I20),IF(K20="", "", K20)) | O20: =IF(COUNTA(L20:N20)>0,SUM(L20:N20),IF(P20="", "", P20)) | S20: =IF(OR(C20="",J20="",O20=""),"",C20+J20-O20) | W20: =IF(Z20=1,"FALTAN DATOS",IF(S20<0,"OCUPACION NEGATIVA",IF(X20=1,"SOBREOCUPACION",IF(Y20<>0,"BALANCE RARO","OK")))) | X20: =IF(AND(R20<>"",S20>R20),1,0) | Y20: =IF(OR(C20="",J20="",O20="",S20=""),"",C20+J20-O20-S20) | Z20: =IF(OR(R20="",A20="",B20="",C20="",J20="",O20=""),1,0)
A21: =DATE(2024,12,15) | B21: 15 | C21: =Q20 | J21: =IF(COUNTA(D21:I21)>0,SUM(D21:I21),IF(K21="", "", K21)) | O21: =IF(COUNTA(L21:N21)>0,SUM(L21:N21),IF(P21="", "", P21)) | S21: =IF(OR(C21="",J21="",O21=""),"",C21+J21-O21) | W21: =IF(Z21=1,"FALTAN DATOS",IF(S21<0,"OCUPACION NEGATIVA",IF(X21=1,"SOBREOCUPACION",IF(Y21<>0,"BALANCE RARO","OK")))) | X21: =IF(AND(R21<>"",S21>R21),1,0) | Y21: =IF(OR(C21="",J21="",O21="",S21=""),"",C21+J21-O21-S21) | Z21: =IF(OR(R21="",A21="",B21="",C21="",J21="",O21=""),1,0)
A22: =DATE(2024,12,16) | B22: 16 | C22: =Q21 | J22: =IF(COUNTA(D22:I22)>0,SUM(D22:I22),IF(K22="", "", K22)) | O22: =IF(COUNTA(L22:N22)>0,SUM(L22:N22),IF(P22="", "", P22)) | S22: =IF(OR(C22="",J22="",O22=""),"",C22+J22-O22) | W22: =IF(Z22=1,"FALTAN DATOS",IF(S22<0,"OCUPACION NEGATIVA",IF(X22=1,"SOBREOCUPACION",IF(Y22<>0,"BALANCE RARO","OK")))) | X22: =IF(AND(R22<>"",S22>R22),1,0) | Y22: =IF(OR(C22="",J22="",O22="",S22=""),"",C22+J22-O22-S22) | Z22: =IF(OR(R22="",A22="",B22="",C22="",J22="",O22=""),1,0)
A23: =DATE(2024,12,17) | B23: 17 | C23: =Q22 | J23: =IF(COUNTA(D23:I23)>0,SUM(D23:I23),IF(K23="", "", K23)) | O23: =IF(COUNTA(L23:N23)>0,SUM(L23:N23),IF(P23="", "", P23)) | S23: =IF(OR(C23="",J23="",O23=""),"",C23+J23-O23) | W23: =IF(Z23=1,"FALTAN DATOS",IF(S23<0,"OCUPACION NEGATIVA",IF(X23=1,"SOBREOCUPACION",IF(Y23<>0,"BALANCE RARO","OK")))) | X23: =IF(AND(R23<>"",S23>R23),1,0) | Y23: =IF(OR(C23="",J23="",O23="",S23=""),"",C23+J23-O23-S23) | Z23: =IF(OR(R23="",A23="",B23="",C23="",J23="",O23=""),1,0)
A24: =DATE(2024,12,18) | B24: 18 | C24: =Q23 | J24: =IF(COUNTA(D24:I24)>0,SUM(D24:I24),IF(K24="", "", K24)) | O24: =IF(COUNTA(L24:N24)>0,SUM(L24:N24),IF(P24="", "", P24)) | S24: =IF(OR(C24="",J24="",O24=""),"",C24+J24-O24) | W24: =IF(Z24=1,"FALTAN DATOS",IF(S24<0,"OCUPACION NEGATIVA",IF(X24=1,"SOBREOCUPACION",IF(Y24<>0,"BALANCE RARO","OK")))) | X24: =IF(AND(R24<>"",S24>R24),1,0) | Y24: =IF(OR(C24="",J24="",O24="",S24=""),"",C24+J24-O24-S24) | Z24: =IF(OR(R24="",A24="",B24="",C24="",J24="",O24=""),1,0)
A25: =DATE(2024,12,19) | B25: 19 | C25: =Q24 | J25: =IF(COUNTA(D25:I25)>0,SUM(D25:I25),IF(K25="", "", K25)) | O25: =IF(COUNTA(L25:N25)>0,SUM(L25:N25),IF(P25="", "", P25)) | S25: =IF(OR(C25="",J25="",O25=""),"",C25+J25-O25) | W25: =IF(Z25=1,"FALTAN DATOS",IF(S25<0,"OCUPACION NEGATIVA",IF(X25=1,"SOBREOCUPACION",IF(Y25<>0,"BALANCE RARO","OK")))) | X25: =IF(AND(R25<>"",S25>R25),1,0) | Y25: =IF(OR(C25="",J25="",O25="",S25=""),"",C25+J25-O25-S25) | Z25: =IF(OR(R25="",A25="",B25="",C25="",J25="",O25=""),1,0)
A26: =DATE(2024,12,20) | B26: 20 | C26: =Q25 | J26: =IF(COUNTA(D26:I26)>0,SUM(D26:I26),IF(K26="", "", K26)) | O26: =IF(COUNTA(L26:N26)>0,SUM(L26:N26),IF(P26="", "", P26)) | S26: =IF(OR(C26="",J26="",O26=""),"",C26+J26-O26) | W26: =IF(Z26=1,"FALTAN DATOS",IF(S26<0,"OCUPACION NEGATIVA",IF(X26=1,"SOBREOCUPACION",IF(Y26<>0,"BALANCE RARO","OK")))) | X26: =IF(AND(R26<>"",S26>R26),1,0) | Y26: =IF(OR(C26="",J26="",O26="",S26=""),"",C26+J26-O26-S26) | Z26: =IF(OR(R26="",A26="",B26="",C26="",J26="",O26=""),1,0)
A27: =DATE(2024,12,21) | B27: 21 | C27: =Q26 | J27: =IF(COUNTA(D27:I27)>0,SUM(D27:I27),IF(K27="", "", K27)) | O27: =IF(COUNTA(L27:N27)>0,SUM(L27:N27),IF(P27="", "", P27)) | S27: =IF(OR(C27="",J27="",O27=""),"",C27+J27-O27) | W27: =IF(Z27=1,"FALTAN DATOS",IF(S27<0,"OCUPACION NEGATIVA",IF(X27=1,"SOBREOCUPACION",IF(Y27<>0,"BALANCE RARO","OK")))) | X27: =IF(AND(R27<>"",S27>R27),1,0) | Y27: =IF(OR(C27="",J27="",O27="",S27=""),"",C27+J27-O27-S27) | Z27: =IF(OR(R27="",A27="",B27="",C27="",J27="",O27=""),1,0)
A28: =DATE(2024,12,22) | B28: 22 | C28: =Q27 | J28: =IF(COUNTA(D28:I28)>0,SUM(D28:I28),IF(K28="", "", K28)) | O28: =IF(COUNTA(L28:N28)>0,SUM(L28:N28),IF(P28="", "", P28)) | S28: =IF(OR(C28="",J28="",O28=""),"",C28+J28-O28) | W28: =IF(Z28=1,"FALTAN DATOS",IF(S28<0,"OCUPACION NEGATIVA",IF(X28=1,"SOBREOCUPACION",IF(Y28<>0,"BALANCE RARO","OK")))) | X28: =IF(AND(R28<>"",S28>R28),1,0) | Y28: =IF(OR(C28="",J28="",O28="",S28=""),"",C28+J28-O28-S28) | Z28: =IF(OR(R28="",A28="",B28="",C28="",J28="",O28=""),1,0)
A29: =DATE(2024,12,23) | B29: 23 | C29: =Q28 | J29: =IF(COUNTA(D29:I29)>0,SUM(D29:I29),IF(K29="", "", K29)) | O29: =IF(COUNTA(L29:N29)>0,SUM(L29:N29),IF(P29="", "", P29)) | S29: =IF(OR(C29="",J29="",O29=""),"",C29+J29-O29) | W29: =IF(Z29=1,"FALTAN DATOS",IF(S29<0,"OCUPACION NEGATIVA",IF(X29=1,"SOBREOCUPACION",IF(Y29<>0,"BALANCE RARO","OK")))) | X29: =IF(AND(R29<>"",S29>R29),1,0) | Y29: =IF(OR(C29="",J29="",O29="",S29=""),"",C29+J29-O29-S29) | Z29: =IF(OR(R29="",A29="",B29="",C29="",J29="",O29=""),1,0)
A30: =DATE(2024,12,24) | B30: 24 | C30: =Q29 | J30: =IF(COUNTA(D30:I30)>0,SUM(D30:I30),IF(K30="", "", K30)) | O30: =IF(COUNTA(L30:N30)>0,SUM(L30:N30),IF(P30="", "", P30)) | S30: =IF(OR(C30="",J30="",O30=""),"",C30+J30-O30) | W30: =IF(Z30=1,"FALTAN DATOS",IF(S30<0,"OCUPACION NEGATIVA",IF(X30=1,"SOBREOCUPACION",IF(Y30<>0,"BALANCE RARO","OK")))) | X30: =IF(AND(R30<>"",S30>R30),1,0) | Y30: =IF(OR(C30="",J30="",O30="",S30=""),"",C30+J30-O30-S30) | Z30: =IF(OR(R30="",A30="",B30="",C30="",J30="",O30=""),1,0)
A31: =DATE(2024,12,25) | B31: 25 | C31: =Q30 | J31: =IF(COUNTA(D31:I31)>0,SUM(D31:I31),IF(K31="", "", K31)) | O31: =IF(COUNTA(L31:N31)>0,SUM(L31:N31),IF(P31="", "", P31)) | S31: =IF(OR(C31="",J31="",O31=""),"",C31+J31-O31) | W31: =IF(Z31=1,"FALTAN DATOS",IF(S31<0,"OCUPACION NEGATIVA",IF(X31=1,"SOBREOCUPACION",IF(Y31<>0,"BALANCE RARO","OK")))) | X31: =IF(AND(R31<>"",S31>R31),1,0) | Y31: =IF(OR(C31="",J31="",O31="",S31=""),"",C31+J31-O31-S31) | Z31: =IF(OR(R31="",A31="",B31="",C31="",J31="",O31=""),1,0)
A32: =DATE(2024,12,26) | B32: 26 | C32: =Q31 | J32: =IF(COUNTA(D32:I32)>0,SUM(D32:I32),IF(K32="", "", K32)) | O32: =IF(COUNTA(L32:N32)>0,SUM(L32:N32),IF(P32="", "", P32)) | S32: =IF(OR(C32="",J32="",O32=""),"",C32+J32-O32) | W32: =IF(Z32=1,"FALTAN DATOS",IF(S32<0,"OCUPACION NEGATIVA",IF(X32=1,"SOBREOCUPACION",IF(Y32<>0,"BALANCE RARO","OK")))) | X32: =IF(AND(R32<>"",S32>R32),1,0) | Y32: =IF(OR(C32="",J32="",O32="",S32=""),"",C32+J32-O32-S32) | Z32: =IF(OR(R32="",A32="",B32="",C32="",J32="",O32=""),1,0)
A33: =DATE(2024,12,27) | B33: 27 | C33: =Q32 | J33: =IF(COUNTA(D33:I33)>0,SUM(D33:I33),IF(K33="", "", K33)) | O33: =IF(COUNTA(L33:N33)>0,SUM(L33:N33),IF(P33="", "", P33)) | S33: =IF(OR(C33="",J33="",O33=""),"",C33+J33-O33) | W33: =IF(Z33=1,"FALTAN DATOS",IF(S33<0,"OCUPACION NEGATIVA",IF(X33=1,"SOBREOCUPACION",IF(Y33<>0,"BALANCE RARO","OK")))) | X33: =IF(AND(R33<>"",S33>R33),1,0) | Y33: =IF(OR(C33="",J33="",O33="",S33=""),"",C33+J33-O33-S33) | Z33: =IF(OR(R33="",A33="",B33="",C33="",J33="",O33=""),1,0)
A34: =DATE(2024,12,28) | B34: 28 | C34: =Q33 | J34: =IF(COUNTA(D34:I34)>0,SUM(D34:I34),IF(K34="", "", K34)) | O34: =IF(COUNTA(L34:N34)>0,SUM(L34:N34),IF(P34="", "", P34)) | S34: =IF(OR(C34="",J34="",O34=""),"",C34+J34-O34) | W34: =IF(Z34=1,"FALTAN DATOS",IF(S34<0,"OCUPACION NEGATIVA",IF(X34=1,"SOBREOCUPACION",IF(Y34<>0,"BALANCE RARO","OK")))) | X34: =IF(AND(R34<>"",S34>R34),1,0) | Y34: =IF(OR(C34="",J34="",O34="",S34=""),"",C34+J34-O34-S34) | Z34: =IF(OR(R34="",A34="",B34="",C34="",J34="",O34=""),1,0)
A35: =DATE(2024,12,29) | B35: 29 | C35: =Q34 | J35: =IF(COUNTA(D35:I35)>0,SUM(D35:I35),IF(K35="", "", K35)) | O35: =IF(COUNTA(L35:N35)>0,SUM(L35:N35),IF(P35="", "", P35)) | S35: =IF(OR(C35="",J35="",O35=""),"",C35+J35-O35) | W35: =IF(Z35=1,"FALTAN DATOS",IF(S35<0,"OCUPACION NEGATIVA",IF(X35=1,"SOBREOCUPACION",IF(Y35<>0,"BALANCE RARO","OK")))) | X35: =IF(AND(R35<>"",S35>R35),1,0) | Y35: =IF(OR(C35="",J35="",O35="",S35=""),"",C35+J35-O35-S35) | Z35: =IF(OR(R35="",A35="",B35="",C35="",J35="",O35=""),1,0)
A36: =DATE(2024,12,30) | B36: 30 | C36: =Q35 | J36: =IF(COUNTA(D36:I36)>0,SUM(D36:I36),IF(K36="", "", K36)) | O36: =IF(COUNTA(L36:N36)>0,SUM(L36:N36),IF(P36="", "", P36)) | S36: =IF(OR(C36="",J36="",O36=""),"",C36+J36-O36) | W36: =IF(Z36=1,"FALTAN DATOS",IF(S36<0,"OCUPACION NEGATIVA",IF(X36=1,"SOBREOCUPACION",IF(Y36<>0,"BALANCE RARO","OK")))) | X36: =IF(AND(R36<>"",S36>R36),1,0) | Y36: =IF(OR(C36="",J36="",O36="",S36=""),"",C36+J36-O36-S36) | Z36: =IF(OR(R36="",A36="",B36="",C36="",J36="",O36=""),1,0)
A37: =DATE(2024,12,31) | B37: 31 | C37: =Q36 | J37: =IF(COUNTA(D37:I37)>0,SUM(D37:I37),IF(K37="", "", K37)) | O37: =IF(COUNTA(L37:N37)>0,SUM(L37:N37),IF(P37="", "", P37)) | S37: =IF(OR(C37="",J37="",O37=""),"",C37+J37-O37) | W37: =IF(Z37=1,"FALTAN DATOS",IF(S37<0,"OCUPACION NEGATIVA",IF(X37=1,"SOBREOCUPACION",IF(Y37<>0,"BALANCE RARO","OK")))) | X37: =IF(AND(R37<>"",S37>R37),1,0) | Y37: =IF(OR(C37="",J37="",O37="",S37=""),"",C37+J37-O37-S37) | Z37: =IF(OR(R37="",A37="",B37="",C37="",J37="",O37=""),1,0)
A38: TOTAL | D38: =SUM(D7:D37) | E38: =SUM(E7:E37) | F38: =SUM(F7:F37) | G38: =SUM(G7:G37) | H38: =SUM(H7:H37) | I38: =SUM(I7:I37) | J38: =SUM(J7:J37) | K38: =SUM(K7:K37) | ... V38: =SUM(V7:V37)
A41: RESUMEN DEL MES | F41: CONTROL DEL MES
A42: Total ingresos | B42: =J38 | F42: Balance debe ser 0 | G42: =IF(B53=0,"OK","REVISAR")
A43: Total egresos | B43: =O38 | F43: No debe haber ocupacion negativa | G43: =IF(COUNTIF(W7:W37,"OCUPACION NEGATIVA")=0,"OK","REVISAR")
A44: Altas hogar / otro hosp. | B44: =L38 | F44: No deberia faltar existencia inicial | G44: =IF(C7="","REVISAR","OK")
A45: Traslados a otro servicio | B45: =M38 | F45: Dias con alertas | G45: =B55
...

Sheet ENERO 2025
A1: HODOM - ENERO 2025
A2: Servicio | B2: =01_PARAMETROS!B3 | C2: Codigo | D2: =01_PARAMETROS!B4 | E2: Mes | F2: ENERO | G2: Ano | H2: 2025 | I2: Camas base | J2: =01_PARAMETROS!B5 | K2: Dias del mes | L2: 31
A6: Fecha | B6: Dia | C6: Existencia inicial | D6: Ing. urgencia | E6: Ing. hospitalizacion | F6: Ing. ambulatorio | G6: Ing. ley urgencia | H6: Ing. UGCC | I6: Ing. traslado | J6: Total ingresos | K6: Total ingresos informado | L6: Alta hogar / otro hosp. | M6: Traslado a otro servicio | N6: Fallecidos | O6: Total egresos | P6: Total egresos informado | Q6: Ingr.-egr. mismo dia | R6: Camas disponibles | S6: Camas ocupadas | T6: Dias estada total | U6: Dias estada benef. | V6: Observaciones | W6: Estado dia | X6: Check camas | Y6: Check balance | Z6: Check faltantes
A7: =DATE(2025,1,1) | B7: 1 | J7: =IF(COUNTA(D7:I7)>0,SUM(D7:I7),IF(K7="", "", K7)) | O7: =IF(COUNTA(L7:N7)>0,SUM(L7:N7),IF(P7="", "", P7)) | S7: =IF(OR(C7="",J7="",O7=""),"",C7+J7-O7) | W7: =IF(Z7=1,"FALTAN DATOS",IF(S7<0,"OCUPACION NEGATIVA",IF(X7=1,"SOBREOCUPACION",IF(Y7<>0,"BALANCE RARO","OK")))) | X7: =IF(AND(R7<>"",S7>R7),1,0) | Y7: =IF(OR(C7="",J7="",O7="",S7=""),"",C7+J7-O7-S7) | Z7: =IF(OR(R7="",A7="",B7="",C7="",J7="",O7=""),1,0)
A8: =DATE(2025,1,2) | B8: 2 | C8: =Q7 | J8: =IF(COUNTA(D8:I8)>0,SUM(D8:I8),IF(K8="", "", K8)) | O8: =IF(COUNTA(L8:N8)>0,SUM(L8:N8),IF(P8="", "", P8)) | S8: =IF(OR(C8="",J8="",O8=""),"",C8+J8-O8) | W8: =IF(Z8=1,"FALTAN DATOS",IF(S8<0,"OCUPACION NEGATIVA",IF(X8=1,"SOBREOCUPACION",IF(Y8<>0,"BALANCE RARO","OK")))) | X8: =IF(AND(R8<>"",S8>R8),1,0) | Y8: =IF(OR(C8="",J8="",O8="",S8=""),"",C8+J8-O8-S8) | Z8: =IF(OR(R8="",A8="",B8="",C8="",J8="",O8=""),1,0)
A9: =DATE(2025,1,3) | B9: 3 | C9: =Q8 | J9: =IF(COUNTA(D9:I9)>0,SUM(D9:I9),IF(K9="", "", K9)) | O9: =IF(COUNTA(L9:N9)>0,SUM(L9:N9),IF(P9="", "", P9)) | S9: =IF(OR(C9="",J9="",O9=""),"",C9+J9-O9) | W9: =IF(Z9=1,"FALTAN DATOS",IF(S9<0,"OCUPACION NEGATIVA",IF(X9=1,"SOBREOCUPACION",IF(Y9<>0,"BALANCE RARO","OK")))) | X9: =IF(AND(R9<>"",S9>R9),1,0) | Y9: =IF(OR(C9="",J9="",O9="",S9=""),"",C9+J9-O9-S9) | Z9: =IF(OR(R9="",A9="",B9="",C9="",J9="",O9=""),1,0)
A10: =DATE(2025,1,4) | B10: 4 | C10: =Q9 | J10: =IF(COUNTA(D10:I10)>0,SUM(D10:I10),IF(K10="", "", K10)) | O10: =IF(COUNTA(L10:N10)>0,SUM(L10:N10),IF(P10="", "", P10)) | S10: =IF(OR(C10="",J10="",O10=""),"",C10+J10-O10) | W10: =IF(Z10=1,"FALTAN DATOS",IF(S10<0,"OCUPACION NEGATIVA",IF(X10=1,"SOBREOCUPACION",IF(Y10<>0,"BALANCE RARO","OK")))) | X10: =IF(AND(R10<>"",S10>R10),1,0) | Y10: =IF(OR(C10="",J10="",O10="",S10=""),"",C10+J10-O10-S10) | Z10: =IF(OR(R10="",A10="",B10="",C10="",J10="",O10=""),1,0)
A11: =DATE(2025,1,5) | B11: 5 | C11: =Q10 | J11: =IF(COUNTA(D11:I11)>0,SUM(D11:I11),IF(K11="", "", K11)) | O11: =IF(COUNTA(L11:N11)>0,SUM(L11:N11),IF(P11="", "", P11)) | S11: =IF(OR(C11="",J11="",O11=""),"",C11+J11-O11) | W11: =IF(Z11=1,"FALTAN DATOS",IF(S11<0,"OCUPACION NEGATIVA",IF(X11=1,"SOBREOCUPACION",IF(Y11<>0,"BALANCE RARO","OK")))) | X11: =IF(AND(R11<>"",S11>R11),1,0) | Y11: =IF(OR(C11="",J11="",O11="",S11=""),"",C11+J11-O11-S11) | Z11: =IF(OR(R11="",A11="",B11="",C11="",J11="",O11=""),1,0)
A12: =DATE(2025,1,6) | B12: 6 | C12: =Q11 | J12: =IF(COUNTA(D12:I12)>0,SUM(D12:I12),IF(K12="", "", K12)) | O12: =IF(COUNTA(L12:N12)>0,SUM(L12:N12),IF(P12="", "", P12)) | S12: =IF(OR(C12="",J12="",O12=""),"",C12+J12-O12) | W12: =IF(Z12=1,"FALTAN DATOS",IF(S12<0,"OCUPACION NEGATIVA",IF(X12=1,"SOBREOCUPACION",IF(Y12<>0,"BALANCE RARO","OK")))) | X12: =IF(AND(R12<>"",S12>R12),1,0) | Y12: =IF(OR(C12="",J12="",O12="",S12=""),"",C12+J12-O12-S12) | Z12: =IF(OR(R12="",A12="",B12="",C12="",J12="",O12=""),1,0)
A13: =DATE(2025,1,7) | B13: 7 | C13: =Q12 | J13: =IF(COUNTA(D13:I13)>0,SUM(D13:I13),IF(K13="", "", K13)) | O13: =IF(COUNTA(L13:N13)>0,SUM(L13:N13),IF(P13="", "", P13)) | S13: =IF(OR(C13="",J13="",O13=""),"",C13+J13-O13) | W13: =IF(Z13=1,"FALTAN DATOS",IF(S13<0,"OCUPACION NEGATIVA",IF(X13=1,"SOBREOCUPACION",IF(Y13<>0,"BALANCE RARO","OK")))) | X13: =IF(AND(R13<>"",S13>R13),1,0) | Y13: =IF(OR(C13="",J13="",O13="",S13=""),"",C13+J13-O13-S13) | Z13: =IF(OR(R13="",A13="",B13="",C13="",J13="",O13=""),1,0)
A14: =DATE(2025,1,8) | B14: 8 | C14: =Q13 | J14: =IF(COUNTA(D14:I14)>0,SUM(D14:I14),IF(K14="", "", K14)) | O14: =IF(COUNTA(L14:N14)>0,SUM(L14:N14),IF(P14="", "", P14)) | S14: =IF(OR(C14="",J14="",O14=""),"",C14+J14-O14) | W14: =IF(Z14=1,"FALTAN DATOS",IF(S14<0,"OCUPACION NEGATIVA",IF(X14=1,"SOBREOCUPACION",IF(Y14<>0,"BALANCE RARO","OK")))) | X14: =IF(AND(R14<>"",S14>R14),1,0) | Y14: =IF(OR(C14="",J14="",O14="",S14=""),"",C14+J14-O14-S14) | Z14: =IF(OR(R14="",A14="",B14="",C14="",J14="",O14=""),1,0)
A15: =DATE(2025,1,9) | B15: 9 | C15: =Q14 | J15: =IF(COUNTA(D15:I15)>0,SUM(D15:I15),IF(K15="", "", K15)) | O15: =IF(COUNTA(L15:N15)>0,SUM(L15:N15),IF(P15="", "", P15)) | S15: =IF(OR(C15="",J15="",O15=""),"",C15+J15-O15) | W15: =IF(Z15=1,"FALTAN DATOS",IF(S15<0,"OCUPACION NEGATIVA",IF(X15=1,"SOBREOCUPACION",IF(Y15<>0,"BALANCE RARO","OK")))) | X15: =IF(AND(R15<>"",S15>R15),1,0) | Y15: =IF(OR(C15="",J15="",O15="",S15=""),"",C15+J15-O15-S15) | Z15: =IF(OR(R15="",A15="",B15="",C15="",J15="",O15=""),1,0)
A16: =DATE(2025,1,10) | B16: 10 | C16: =Q15 | J16: =IF(COUNTA(D16:I16)>0,SUM(D16:I16),IF(K16="", "", K16)) | O16: =IF(COUNTA(L16:N16)>0,SUM(L16:N16),IF(P16="", "", P16)) | S16: =IF(OR(C16="",J16="",O16=""),"",C16+J16-O16) | W16: =IF(Z16=1,"FALTAN DATOS",IF(S16<0,"OCUPACION NEGATIVA",IF(X16=1,"SOBREOCUPACION",IF(Y16<>0,"BALANCE RARO","OK")))) | X16: =IF(AND(R16<>"",S16>R16),1,0) | Y16: =IF(OR(C16="",J16="",O16="",S16=""),"",C16+J16-O16-S16) | Z16: =IF(OR(R16="",A16="",B16="",C16="",J16="",O16=""),1,0)
A17: =DATE(2025,1,11) | B17: 11 | C17: =Q16 | J17: =IF(COUNTA(D17:I17)>0,SUM(D17:I17),IF(K17="", "", K17)) | O17: =IF(COUNTA(L17:N17)>0,SUM(L17:N17),IF(P17="", "", P17)) | S17: =IF(OR(C17="",J17="",O17=""),"",C17+J17-O17) | W17: =IF(Z17=1,"FALTAN DATOS",IF(S17<0,"OCUPACION NEGATIVA",IF(X17=1,"SOBREOCUPACION",IF(Y17<>0,"BALANCE RARO","OK")))) | X17: =IF(AND(R17<>"",S17>R17),1,0) | Y17: =IF(OR(C17="",J17="",O17="",S17=""),"",C17+J17-O17-S17) | Z17: =IF(OR(R17="",A17="",B17="",C17="",J17="",O17=""),1,0)
A18: =DATE(2025,1,12) | B18: 12 | C18: =Q17 | J18: =IF(COUNTA(D18:I18)>0,SUM(D18:I18),IF(K18="", "", K18)) | O18: =IF(COUNTA(L18:N18)>0,SUM(L18:N18),IF(P18="", "", P18)) | S18: =IF(OR(C18="",J18="",O18=""),"",C18+J18-O18) | W18: =IF(Z18=1,"FALTAN DATOS",IF(S18<0,"OCUPACION NEGATIVA",IF(X18=1,"SOBREOCUPACION",IF(Y18<>0,"BALANCE RARO","OK")))) | X18: =IF(AND(R18<>"",S18>R18),1,0) | Y18: =IF(OR(C18="",J18="",O18="",S18=""),"",C18+J18-O18-S18) | Z18: =IF(OR(R18="",A18="",B18="",C18="",J18="",O18=""),1,0)
A19: =DATE(2025,1,13) | B19: 13 | C19: =Q18 | J19: =IF(COUNTA(D19:I19)>0,SUM(D19:I19),IF(K19="", "", K19)) | O19: =IF(COUNTA(L19:N19)>0,SUM(L19:N19),IF(P19="", "", P19)) | S19: =IF(OR(C19="",J19="",O19=""),"",C19+J19-O19) | W19: =IF(Z19=1,"FALTAN DATOS",IF(S19<0,"OCUPACION NEGATIVA",IF(X19=1,"SOBREOCUPACION",IF(Y19<>0,"BALANCE RARO","OK")))) | X19: =IF(AND(R19<>"",S19>R19),1,0) | Y19: =IF(OR(C19="",J19="",O19="",S19=""),"",C19+J19-O19-S19) | Z19: =IF(OR(R19="",A19="",B19="",C19="",J19="",O19=""),1,0)
A20: =DATE(2025,1,14) | B20: 14 | C20: =Q19 | J20: =IF(COUNTA(D20:I20)>0,SUM(D20:I20),IF(K20="", "", K20)) | O20: =IF(COUNTA(L20:N20)>0,SUM(L20:N20),IF(P20="", "", P20)) | S20: =IF(OR(C20="",J20="",O20=""),"",C20+J20-O20) | W20: =IF(Z20=1,"FALTAN DATOS",IF(S20<0,"OCUPACION NEGATIVA",IF(X20=1,"SOBREOCUPACION",IF(Y20<>0,"BALANCE RARO","OK")))) | X20: =IF(AND(R20<>"",S20>R20),1,0) | Y20: =IF(OR(C20="",J20="",O20="",S20=""),"",C20+J20-O20-S20) | Z20: =IF(OR(R20="",A20="",B20="",C20="",J20="",O20=""),1,0)
A21: =DATE(2025,1,15) | B21: 15 | C21: =Q20 | J21: =IF(COUNTA(D21:I21)>0,SUM(D21:I21),IF(K21="", "", K21)) | O21: =IF(COUNTA(L21:N21)>0,SUM(L21:N21),IF(P21="", "", P21)) | S21: =IF(OR(C21="",J21="",O21=""),"",C21+J21-O21) | W21: =IF(Z21=1,"FALTAN DATOS",IF(S21<0,"OCUPACION NEGATIVA",IF(X21=1,"SOBREOCUPACION",IF(Y21<>0,"BALANCE RARO","OK")))) | X21: =IF(AND(R21<>"",S21>R21),1,0) | Y21: =IF(OR(C21="",J21="",O21="",S21=""),"",C21+J21-O21-S21) | Z21: =IF(OR(R21="",A21="",B21="",C21="",J21="",O21=""),1,0)
A22: =DATE(2025,1,16) | B22: 16 | C22: =Q21 | J22: =IF(COUNTA(D22:I22)>0,SUM(D22:I22),IF(K22="", "", K22)) | O22: =IF(COUNTA(L22:N22)>0,SUM(L22:N22),IF(P22="", "", P22)) | S22: =IF(OR(C22="",J22="",O22=""),"",C22+J22-O22) | W22: =IF(Z22=1,"FALTAN DATOS",IF(S22<0,"OCUPACION NEGATIVA",IF(X22=1,"SOBREOCUPACION",IF(Y22<>0,"BALANCE RARO","OK")))) | X22: =IF(AND(R22<>"",S22>R22),1,0) | Y22: =IF(OR(C22="",J22="",O22="",S22=""),"",C22+J22-O22-S22) | Z22: =IF(OR(R22="",A22="",B22="",C22="",J22="",O22=""),1,0)
A23: =DATE(2025,1,17) | B23: 17 | C23: =Q22 | J23: =IF(COUNTA(D23:I23)>0,SUM(D23:I23),IF(K23="", "", K23)) | O23: =IF(COUNTA(L23:N23)>0,SUM(L23:N23),IF(P23="", "", P23)) | S23: =IF(OR(C23="",J23="",O23=""),"",C23+J23-O23) | W23: =IF(Z23=1,"FALTAN DATOS",IF(S23<0,"OCUPACION NEGATIVA",IF(X23=1,"SOBREOCUPACION",IF(Y23<>0,"BALANCE RARO","OK")))) | X23: =IF(AND(R23<>"",S23>R23),1,0) | Y23: =IF(OR(C23="",J23="",O23="",S23=""),"",C23+J23-O23-S23) | Z23: =IF(OR(R23="",A23="",B23="",C23="",J23="",O23=""),1,0)
A24: =DATE(2025,1,18) | B24: 18 | C24: =Q23 | J24: =IF(COUNTA(D24:I24)>0,SUM(D24:I24),IF(K24="", "", K24)) | O24: =IF(COUNTA(L24:N24)>0,SUM(L24:N24),IF(P24="", "", P24)) | S24: =IF(OR(C24="",J24="",O24=""),"",C24+J24-O24) | W24: =IF(Z24=1,"FALTAN DATOS",IF(S24<0,"OCUPACION NEGATIVA",IF(X24=1,"SOBREOCUPACION",IF(Y24<>0,"BALANCE RARO","OK")))) | X24: =IF(AND(R24<>"",S24>R24),1,0) | Y24: =IF(OR(C24="",J24="",O24="",S24=""),"",C24+J24-O24-S24) | Z24: =IF(OR(R24="",A24="",B24="",C24="",J24="",O24=""),1,0)
A25: =DATE(2025,1,19) | B25: 19 | C25: =Q24 | J25: =IF(COUNTA(D25:I25)>0,SUM(D25:I25),IF(K25="", "", K25)) | O25: =IF(COUNTA(L25:N25)>0,SUM(L25:N25),IF(P25="", "", P25)) | S25: =IF(OR(C25="",J25="",O25=""),"",C25+J25-O25) | W25: =IF(Z25=1,"FALTAN DATOS",IF(S25<0,"OCUPACION NEGATIVA",IF(X25=1,"SOBREOCUPACION",IF(Y25<>0,"BALANCE RARO","OK")))) | X25: =IF(AND(R25<>"",S25>R25),1,0) | Y25: =IF(OR(C25="",J25="",O25="",S25=""),"",C25+J25-O25-S25) | Z25: =IF(OR(R25="",A25="",B25="",C25="",J25="",O25=""),1,0)
A26: =DATE(2025,1,20) | B26: 20 | C26: =Q25 | J26: =IF(COUNTA(D26:I26)>0,SUM(D26:I26),IF(K26="", "", K26)) | O26: =IF(COUNTA(L26:N26)>0,SUM(L26:N26),IF(P26="", "", P26)) | S26: =IF(OR(C26="",J26="",O26=""),"",C26+J26-O26) | W26: =IF(Z26=1,"FALTAN DATOS",IF(S26<0,"OCUPACION NEGATIVA",IF(X26=1,"SOBREOCUPACION",IF(Y26<>0,"BALANCE RARO","OK")))) | X26: =IF(AND(R26<>"",S26>R26),1,0) | Y26: =IF(OR(C26="",J26="",O26="",S26=""),"",C26+J26-O26-S26) | Z26: =IF(OR(R26="",A26="",B26="",C26="",J26="",O26=""),1,0)
A27: =DATE(2025,1,21) | B27: 21 | C27: =Q26 | J27: =IF(COUNTA(D27:I27)>0,SUM(D27:I27),IF(K27="", "", K27)) | O27: =IF(COUNTA(L27:N27)>0,SUM(L27:N27),IF(P27="", "", P27)) | S27: =IF(OR(C27="",J27="",O27=""),"",C27+J27-O27) | W27: =IF(Z27=1,"FALTAN DATOS",IF(S27<0,"OCUPACION NEGATIVA",IF(X27=1,"SOBREOCUPACION",IF(Y27<>0,"BALANCE RARO","OK")))) | X27: =IF(AND(R27<>"",S27>R27),1,0) | Y27: =IF(OR(C27="",J27="",O27="",S27=""),"",C27+J27-O27-S27) | Z27: =IF(OR(R27="",A27="",B27="",C27="",J27="",O27=""),1,0)
A28: =DATE(2025,1,22) | B28: 22 | C28: =Q27 | J28: =IF(COUNTA(D28:I28)>0,SUM(D28:I28),IF(K28="", "", K28)) | O28: =IF(COUNTA(L28:N28)>0,SUM(L28:N28),IF(P28="", "", P28)) | S28: =IF(OR(C28="",J28="",O28=""),"",C28+J28-O28) | W28: =IF(Z28=1,"FALTAN DATOS",IF(S28<0,"OCUPACION NEGATIVA",IF(X28=1,"SOBREOCUPACION",IF(Y28<>0,"BALANCE RARO","OK")))) | X28: =IF(AND(R28<>"",S28>R28),1,0) | Y28: =IF(OR(C28="",J28="",O28="",S28=""),"",C28+J28-O28-S28) | Z28: =IF(OR(R28="",A28="",B28="",C28="",J28="",O28=""),1,0)
A29: =DATE(2025,1,23) | B29: 23 | C29: =Q28 | J29: =IF(COUNTA(D29:I29)>0,SUM(D29:I29),IF(K29="", "", K29)) | O29: =IF(COUNTA(L29:N29)>0,SUM(L29:N29),IF(P29="", "", P29)) | S29: =IF(OR(C29="",J29="",O29=""),"",C29+J29-O29) | W29: =IF(Z29=1,"FALTAN DATOS",IF(S29<0,"OCUPACION NEGATIVA",IF(X29=1,"SOBREOCUPACION",IF(Y29<>0,"BALANCE RARO","OK")))) | X29: =IF(AND(R29<>"",S29>R29),1,0) | Y29: =IF(OR(C29="",J29="",O29="",S29=""),"",C29+J29-O29-S29) | Z29: =IF(OR(R29="",A29="",B29="",C29="",J29="",O29=""),1,0)
A30: =DATE(2025,1,24) | B30: 24 | C30: =Q29 | J30: =IF(COUNTA(D30:I30)>0,SUM(D30:I30),IF(K30="", "", K30)) | O30: =IF(COUNTA(L30:N30)>0,SUM(L30:N30),IF(P30="", "", P30)) | S30: =IF(OR(C30="",J30="",O30=""),"",C30+J30-O30) | W30: =IF(Z30=1,"FALTAN DATOS",IF(S30<0,"OCUPACION NEGATIVA",IF(X30=1,"SOBREOCUPACION",IF(Y30<>0,"BALANCE RARO","OK")))) | X30: =IF(AND(R30<>"",S30>R30),1,0) | Y30: =IF(OR(C30="",J30="",O30="",S30=""),"",C30+J30-O30-S30) | Z30: =IF(OR(R30="",A30="",B30="",C30="",J30="",O30=""),1,0)
A31: =DATE(2025,1,25) | B31: 25 | C31: =Q30 | J31: =IF(COUNTA(D31:I31)>0,SUM(D31:I31),IF(K31="", "", K31)) | O31: =IF(COUNTA(L31:N31)>0,SUM(L31:N31),IF(P31="", "", P31)) | S31: =IF(OR(C31="",J31="",O31=""),"",C31+J31-O31) | W31: =IF(Z31=1,"FALTAN DATOS",IF(S31<0,"OCUPACION NEGATIVA",IF(X31=1,"SOBREOCUPACION",IF(Y31<>0,"BALANCE RARO","OK")))) | X31: =IF(AND(R31<>"",S31>R31),1,0) | Y31: =IF(OR(C31="",J31="",O31="",S31=""),"",C31+J31-O31-S31) | Z31: =IF(OR(R31="",A31="",B31="",C31="",J31="",O31=""),1,0)
A32: =DATE(2025,1,26) | B32: 26 | C32: =Q31 | J32: =IF(COUNTA(D32:I32)>0,SUM(D32:I32),IF(K32="", "", K32)) | O32: =IF(COUNTA(L32:N32)>0,SUM(L32:N32),IF(P32="", "", P32)) | S32: =IF(OR(C32="",J32="",O32=""),"",C32+J32-O32) | W32: =IF(Z32=1,"FALTAN DATOS",IF(S32<0,"OCUPACION NEGATIVA",IF(X32=1,"SOBREOCUPACION",IF(Y32<>0,"BALANCE RARO","OK")))) | X32: =IF(AND(R32<>"",S32>R32),1,0) | Y32: =IF(OR(C32="",J32="",O32="",S32=""),"",C32+J32-O32-S32) | Z32: =IF(OR(R32="",A32="",B32="",C32="",J32="",O32=""),1,0)
A33: =DATE(2025,1,27) | B33: 27 | C33: =Q32 | J33: =IF(COUNTA(D33:I33)>0,SUM(D33:I33),IF(K33="", "", K33)) | O33: =IF(COUNTA(L33:N33)>0,SUM(L33:N33),IF(P33="", "", P33)) | S33: =IF(OR(C33="",J33="",O33=""),"",C33+J33-O33) | W33: =IF(Z33=1,"FALTAN DATOS",IF(S33<0,"OCUPACION NEGATIVA",IF(X33=1,"SOBREOCUPACION",IF(Y33<>0,"BALANCE RARO","OK")))) | X33: =IF(AND(R33<>"",S33>R33),1,0) | Y33: =IF(OR(C33="",J33="",O33="",S33=""),"",C33+J33-O33-S33) | Z33: =IF(OR(R33="",A33="",B33="",C33="",J33="",O33=""),1,0)
A34: =DATE(2025,1,28) | B34: 28 | C34: =Q33 | J34: =IF(COUNTA(D34:I34)>0,SUM(D34:I34),IF(K34="", "", K34)) | O34: =IF(COUNTA(L34:N34)>0,SUM(L34:N34),IF(P34="", "", P34)) | S34: =IF(OR(C34="",J34="",O34=""),"",C34+J34-O34) | W34: =IF(Z34=1,"FALTAN DATOS",IF(S34<0,"OCUPACION NEGATIVA",IF(X34=1,"SOBREOCUPACION",IF(Y34<>0,"BALANCE RARO","OK")))) | X34: =IF(AND(R34<>"",S34>R34),1,0) | Y34: =IF(OR(C34="",J34="",O34="",S34=""),"",C34+J34-O34-S34) | Z34: =IF(OR(R34="",A34="",B34="",C34="",J34="",O34=""),1,0)
A35: =DATE(2025,1,29) | B35: 29 | C35: =Q34 | J35: =IF(COUNTA(D35:I35)>0,SUM(D35:I35),IF(K35="", "", K35)) | O35: =IF(COUNTA(L35:N35)>0,SUM(L35:N35),IF(P35="", "", P35)) | S35: =IF(OR(C35="",J35="",O35=""),"",C35+J35-O35) | W35: =IF(Z35=1,"FALTAN DATOS",IF(S35<0,"OCUPACION NEGATIVA",IF(X35=1,"SOBREOCUPACION",IF(Y35<>0,"BALANCE RARO","OK")))) | X35: =IF(AND(R35<>"",S35>R35),1,0) | Y35: =IF(OR(C35="",J35="",O35="",S35=""),"",C35+J35-O35-S35) | Z35: =IF(OR(R35="",A35="",B35="",C35="",J35="",O35=""),1,0)
A36: =DATE(2025,1,30) | B36: 30 | C36: =Q35 | J36: =IF(COUNTA(D36:I36)>0,SUM(D36:I36),IF(K36="", "", K36)) | O36: =IF(COUNTA(L36:N36)>0,SUM(L36:N36),IF(P36="", "", P36)) | S36: =IF(OR(C36="",J36="",O36=""),"",C36+J36-O36) | W36: =IF(Z36=1,"FALTAN DATOS",IF(S36<0,"OCUPACION NEGATIVA",IF(X36=1,"SOBREOCUPACION",IF(Y36<>0,"BALANCE RARO","OK")))) | X36: =IF(AND(R36<>"",S36>R36),1,0) | Y36: =IF(OR(C36="",J36="",O36="",S36=""),"",C36+J36-O36-S36) | Z36: =IF(OR(R36="",A36="",B36="",C36="",J36="",O36=""),1,0)
A37: =DATE(2025,1,31) | B37: 31 | C37: =Q36 | J37: =IF(COUNTA(D37:I37)>0,SUM(D37:I37),IF(K37="", "", K37)) | O37: =IF(COUNTA(L37:N37)>0,SUM(L37:N37),IF(P37="", "", P37)) | S37: =IF(OR(C37="",J37="",O37=""),"",C37+J37-O37) | W37: =IF(Z37=1,"FALTAN DATOS",IF(S37<0,"OCUPACION NEGATIVA",IF(X37=1,"SOBREOCUPACION",IF(Y37<>0,"BALANCE RARO","OK")))) | X37: =IF(AND(R37<>"",S37>R37),1,0) | Y37: =IF(OR(C37="",J37="",O37="",S37=""),"",C37+J37-O37-S37) | Z37: =IF(OR(R37="",A37="",B37="",C37="",J37="",O37=""),1,0)
A38: TOTAL | D38: =SUM(D7:D37) | E38: =SUM(E7:E37) | F38: =SUM(F7:F37) | G38: =SUM(G7:G37) | H38: =SUM(H7:H37) | I38: =SUM(I7:I37) | J38: =SUM(J7:J37) | K38: =SUM(K7:K37) | ... V38: =SUM(V7:V37)
A41: RESUMEN DEL MES | F41: CONTROL DEL MES
A42: Total ingresos | B42: =J38 | F42: Balance debe ser 0 | G42: =IF(B53=0,"OK","REVISAR")
A43: Total egresos | B43: =O38 | F43: No debe haber ocupacion negativa | G43: =IF(COUNTIF(W7:W37,"OCUPACION NEGATIVA")=0,"OK","REVISAR")
A44: Altas hogar / otro hosp. | B44: =L38 | F44: No deberia faltar existencia inicial | G44: =IF(C7="","REVISAR","OK")
A45: Traslados a otro servicio | B45: =M38 | F45: Dias con alertas | G45: =B55
...

Sheet FEBRERO 2025
A1: HODOM - FEBRERO 2025
A2: Servicio | B2: =01_PARAMETROS!B3 | C2: Codigo | D2: =01_PARAMETROS!B4 | E2: Mes | F2: FEBRERO | G2: Ano | H2: 2025 | I2: Camas base | J2: =01_PARAMETROS!B5 | K2: Dias del mes | L2: 28
A6: Fecha | B6: Dia | C6: Existencia inicial | D6: Ing. urgencia | E6: Ing. hospitalizacion | F6: Ing. ambulatorio | G6: Ing. ley urgencia | H6: Ing. UGCC | I6: Ing. traslado | J6: Total ingresos | K6: Total ingresos informado | L6: Alta hogar / otro hosp. | M6: Traslado a otro servicio | N6: Fallecidos | O6: Total egresos | P6: Total egresos informado | Q6: Ingr.-egr. mismo dia | R6: Camas disponibles | S6: Camas ocupadas | T6: Dias estada total | U6: Dias estada benef. | V6: Observaciones | W6: Estado dia | X6: Check camas | Y6: Check balance | Z6: Check faltantes
A7: =DATE(2025,2,1) | B7: 1 | J7: =IF(COUNTA(D7:I7)>0,SUM(D7:I7),IF(K7="", "", K7)) | O7: =IF(COUNTA(L7:N7)>0,SUM(L7:N7),IF(P7="", "", P7)) | S7: =IF(OR(C7="",J7="",O7=""),"",C7+J7-O7) | W7: =IF(Z7=1,"FALTAN DATOS",IF(S7<0,"OCUPACION NEGATIVA",IF(X7=1,"SOBREOCUPACION",IF(Y7<>0,"BALANCE RARO","OK")))) | X7: =IF(AND(R7<>"",S7>R7),1,0) | Y7: =IF(OR(C7="",J7="",O7="",S7=""),"",C7+J7-O7-S7) | Z7: =IF(OR(R7="",A7="",B7="",C7="",J7="",O7=""),1,0)
A8: =DATE(2025,2,2) | B8: 2 | C8: =Q7 | J8: =IF(COUNTA(D8:I8)>0,SUM(D8:I8),IF(K8="", "", K8)) | O8: =IF(COUNTA(L8:N8)>0,SUM(L8:N8),IF(P8="", "", P8)) | S8: =IF(OR(C8="",J8="",O8=""),"",C8+J8-O8) | W8: =IF(Z8=1,"FALTAN DATOS",IF(S8<0,"OCUPACION NEGATIVA",IF(X8=1,"SOBREOCUPACION",IF(Y8<>0,"BALANCE RARO","OK")))) | X8: =IF(AND(R8<>"",S8>R8),1,0) | Y8: =IF(OR(C8="",J8="",O8="",S8=""),"",C8+J8-O8-S8) | Z8: =IF(OR(R8="",A8="",B8="",C8="",J8="",O8=""),1,0)
A9: =DATE(2025,2,3) | B9: 3 | C9: =Q8 | J9: =IF(COUNTA(D9:I9)>0,SUM(D9:I9),IF(K9="", "", K9)) | O9: =IF(COUNTA(L9:N9)>0,SUM(L9:N9),IF(P9="", "", P9)) | S9: =IF(OR(C9="",J9="",O9=""),"",C9+J9-O9) | W9: =IF(Z9=1,"FALTAN DATOS",IF(S9<0,"OCUPACION NEGATIVA",IF(X9=1,"SOBREOCUPACION",IF(Y9<>0,"BALANCE RARO","OK")))) | X9: =IF(AND(R9<>"",S9>R9),1,0) | Y9: =IF(OR(C9="",J9="",O9="",S9=""),"",C9+J9-O9-S9) | Z9: =IF(OR(R9="",A9="",B9="",C9="",J9="",O9=""),1,0)
A10: =DATE(2025,2,4) | B10: 4 | C10: =Q9 | J10: =IF(COUNTA(D10:I10)>0,SUM(D10:I10),IF(K10="", "", K10)) | O10: =IF(COUNTA(L10:N10)>0,SUM(L10:N10),IF(P10="", "", P10)) | S10: =IF(OR(C10="",J10="",O10=""),"",C10+J10-O10) | W10: =IF(Z10=1,"FALTAN DATOS",IF(S10<0,"OCUPACION NEGATIVA",IF(X10=1,"SOBREOCUPACION",IF(Y10<>0,"BALANCE RARO","OK")))) | X10: =IF(AND(R10<>"",S10>R10),1,0) | Y10: =IF(OR(C10="",J10="",O10="",S10=""),"",C10+J10-O10-S10) | Z10: =IF(OR(R10="",A10="",B10="",C10="",J10="",O10=""),1,0)
A11: =DATE(2025,2,5) | B11: 5 | C11: =Q10 | J11: =IF(COUNTA(D11:I11)>0,SUM(D11:I11),IF(K11="", "", K11)) | O11: =IF(COUNTA(L11:N11)>0,SUM(L11:N11),IF(P11="", "", P11)) | S11: =IF(OR(C11="",J11="",O11=""),"",C11+J11-O11) | W11: =IF(Z11=1,"FALTAN DATOS",IF(S11<0,"OCUPACION NEGATIVA",IF(X11=1,"SOBREOCUPACION",IF(Y11<>0,"BALANCE RARO","OK")))) | X11: =IF(AND(R11<>"",S11>R11),1,0) | Y11: =IF(OR(C11="",J11="",O11="",S11=""),"",C11+J11-O11-S11) | Z11: =IF(OR(R11="",A11="",B11="",C11="",J11="",O11=""),1,0)
A12: =DATE(2025,2,6) | B12: 6 | C12: =Q11 | J12: =IF(COUNTA(D12:I12)>0,SUM(D12:I12),IF(K12="", "", K12)) | O12: =IF(COUNTA(L12:N12)>0,SUM(L12:N12),IF(P12="", "", P12)) | S12: =IF(OR(C12="",J12="",O12=""),"",C12+J12-O12) | W12: =IF(Z12=1,"FALTAN DATOS",IF(S12<0,"OCUPACION NEGATIVA",IF(X12=1,"SOBREOCUPACION",IF(Y12<>0,"BALANCE RARO","OK")))) | X12: =IF(AND(R12<>"",S12>R12),1,0) | Y12: =IF(OR(C12="",J12="",O12="",S12=""),"",C12+J12-O12-S12) | Z12: =IF(OR(R12="",A12="",B12="",C12="",J12="",O12=""),1,0)
A13: =DATE(2025,2,7) | B13: 7 | C13: =Q12 | J13: =IF(COUNTA(D13:I13)>0,SUM(D13:I13),IF(K13="", "", K13)) | O13: =IF(COUNTA(L13:N13)>0,SUM(L13:N13),IF(P13="", "", P13)) | S13: =IF(OR(C13="",J13="",O13=""),"",C13+J13-O13) | W13: =IF(Z13=1,"FALTAN DATOS",IF(S13<0,"OCUPACION NEGATIVA",IF(X13=1,"SOBREOCUPACION",IF(Y13<>0,"BALANCE RARO","OK")))) | X13: =IF(AND(R13<>"",S13>R13),1,0) | Y13: =IF(OR(C13="",J13="",O13="",S13=""),"",C13+J13-O13-S13) | Z13: =IF(OR(R13="",A13="",B13="",C13="",J13="",O13=""),1,0)
A14: =DATE(2025,2,8) | B14: 8 | C14: =Q13 | J14: =IF(COUNTA(D14:I14)>0,SUM(D14:I14),IF(K14="", "", K14)) | O14: =IF(COUNTA(L14:N14)>0,SUM(L14:N14),IF(P14="", "", P14)) | S14: =IF(OR(C14="",J14="",O14=""),"",C14+J14-O14) | W14: =IF(Z14=1,"FALTAN DATOS",IF(S14<0,"OCUPACION NEGATIVA",IF(X14=1,"SOBREOCUPACION",IF(Y14<>0,"BALANCE RARO","OK")))) | X14: =IF(AND(R14<>"",S14>R14),1,0) | Y14: =IF(OR(C14="",J14="",O14="",S14=""),"",C14+J14-O14-S14) | Z14: =IF(OR(R14="",A14="",B14="",C14="",J14="",O14=""),1,0)
A15: =DATE(2025,2,9) | B15: 9 | C15: =Q14 | J15: =IF(COUNTA(D15:I15)>0,SUM(D15:I15),IF(K15="", "", K15)) | O15: =IF(COUNTA(L15:N15)>0,SUM(L15:N15),IF(P15="", "", P15)) | S15: =IF(OR(C15="",J15="",O15=""),"",C15+J15-O15) | W15: =IF(Z15=1,"FALTAN DATOS",IF(S15<0,"OCUPACION NEGATIVA",IF(X15=1,"SOBREOCUPACION",IF(Y15<>0,"BALANCE RARO","OK")))) | X15: =IF(AND(R15<>"",S15>R15),1,0) | Y15: =IF(OR(C15="",J15="",O15="",S15=""),"",C15+J15-O15-S15) | Z15: =IF(OR(R15="",A15="",B15="",C15="",J15="",O15=""),1,0)
A16: =DATE(2025,2,10) | B16: 10 | C16: =Q15 | J16: =IF(COUNTA(D16:I16)>0,SUM(D16:I16),IF(K16="", "", K16)) | O16: =IF(COUNTA(L16:N16)>0,SUM(L16:N16),IF(P16="", "", P16)) | S16: =IF(OR(C16="",J16="",O16=""),"",C16+J16-O16) | W16: =IF(Z16=1,"FALTAN DATOS",IF(S16<0,"OCUPACION NEGATIVA",IF(X16=1,"SOBREOCUPACION",IF(Y16<>0,"BALANCE RARO","OK")))) | X16: =IF(AND(R16<>"",S16>R16),1,0) | Y16: =IF(OR(C16="",J16="",O16="",S16=""),"",C16+J16-O16-S16) | Z16: =IF(OR(R16="",A16="",B16="",C16="",J16="",O16=""),1,0)
A17: =DATE(2025,2,11) | B17: 11 | C17: =Q16 | J17: =IF(COUNTA(D17:I17)>0,SUM(D17:I17),IF(K17="", "", K17)) | O17: =IF(COUNTA(L17:N17)>0,SUM(L17:N17),IF(P17="", "", P17)) | S17: =IF(OR(C17="",J17="",O17=""),"",C17+J17-O17) | W17: =IF(Z17=1,"FALTAN DATOS",IF(S17<0,"OCUPACION NEGATIVA",IF(X17=1,"SOBREOCUPACION",IF(Y17<>0,"BALANCE RARO","OK")))) | X17: =IF(AND(R17<>"",S17>R17),1,0) | Y17: =IF(OR(C17="",J17="",O17="",S17=""),"",C17+J17-O17-S17) | Z17: =IF(OR(R17="",A17="",B17="",C17="",J17="",O17=""),1,0)
A18: =DATE(2025,2,12) | B18: 12 | C18: =Q17 | J18: =IF(COUNTA(D18:I18)>0,SUM(D18:I18),IF(K18="", "", K18)) | O18: =IF(COUNTA(L18:N18)>0,SUM(L18:N18),IF(P18="", "", P18)) | S18: =IF(OR(C18="",J18="",O18=""),"",C18+J18-O18) | W18: =IF(Z18=1,"FALTAN DATOS",IF(S18<0,"OCUPACION NEGATIVA",IF(X18=1,"SOBREOCUPACION",IF(Y18<>0,"BALANCE RARO","OK")))) | X18: =IF(AND(R18<>"",S18>R18),1,0) | Y18: =IF(OR(C18="",J18="",O18="",S18=""),"",C18+J18-O18-S18) | Z18: =IF(OR(R18="",A18="",B18="",C18="",J18="",O18=""),1,0)
A19: =DATE(2025,2,13) | B19: 13 | C19: =Q18 | J19: =IF(COUNTA(D19:I19)>0,SUM(D19:I19),IF(K19="", "", K19)) | O19: =IF(COUNTA(L19:N19)>0,SUM(L19:N19),IF(P19="", "", P19)) | S19: =IF(OR(C19="",J19="",O19=""),"",C19+J19-O19) | W19: =IF(Z19=1,"FALTAN DATOS",IF(S19<0,"OCUPACION NEGATIVA",IF(X19=1,"SOBREOCUPACION",IF(Y19<>0,"BALANCE RARO","OK")))) | X19: =IF(AND(R19<>"",S19>R19),1,0) | Y19: =IF(OR(C19="",J19="",O19="",S19=""),"",C19+J19-O19-S19) | Z19: =IF(OR(R19="",A19="",B19="",C19="",J19="",O19=""),1,0)
A20: =DATE(2025,2,14) | B20: 14 | C20: =Q19 | J20: =IF(COUNTA(D20:I20)>0,SUM(D20:I20),IF(K20="", "", K20)) | O20: =IF(COUNTA(L20:N20)>0,SUM(L20:N20),IF(P20="", "", P20)) | S20: =IF(OR(C20="",J20="",O20=""),"",C20+J20-O20) | W20: =IF(Z20=1,"FALTAN DATOS",IF(S20<0,"OCUPACION NEGATIVA",IF(X20=1,"SOBREOCUPACION",IF(Y20<>0,"BALANCE RARO","OK")))) | X20: =IF(AND(R20<>"",S20>R20),1,0) | Y20: =IF(OR(C20="",J20="",O20="",S20=""),"",C20+J20-O20-S20) | Z20: =IF(OR(R20="",A20="",B20="",C20="",J20="",O20=""),1,0)
A21: =DATE(2025,2,15) | B21: 15 | C21: =Q20 | J21: =IF(COUNTA(D21:I21)>0,SUM(D21:I21),IF(K21="", "", K21)) | O21: =IF(COUNTA(L21:N21)>0,SUM(L21:N21),IF(P21="", "", P21)) | S21: =IF(OR(C21="",J21="",O21=""),"",C21+J21-O21) | W21: =IF(Z21=1,"FALTAN DATOS",IF(S21<0,"OCUPACION NEGATIVA",IF(X21=1,"SOBREOCUPACION",IF(Y21<>0,"BALANCE RARO","OK")))) | X21: =IF(AND(R21<>"",S21>R21),1,0) | Y21: =IF(OR(C21="",J21="",O21="",S21=""),"",C21+J21-O21-S21) | Z21: =IF(OR(R21="",A21="",B21="",C21="",J21="",O21=""),1,0)
A22: =DATE(2025,2,16) | B22: 16 | C22: =Q21 | J22: =IF(COUNTA(D22:I22)>0,SUM(D22:I22),IF(K22="", "", K22)) | O22: =IF(COUNTA(L22:N22)>0,SUM(L22:N22),IF(P22="", "", P22)) | S22: =IF(OR(C22="",J22="",O22=""),"",C22+J22-O22) | W22: =IF(Z22=1,"FALTAN DATOS",IF(S22<0,"OCUPACION NEGATIVA",IF(X22=1,"SOBREOCUPACION",IF(Y22<>0,"BALANCE RARO","OK")))) | X22: =IF(AND(R22<>"",S22>R22),1,0) | Y22: =IF(OR(C22="",J22="",O22="",S22=""),"",C22+J22-O22-S22) | Z22: =IF(OR(R22="",A22="",B22="",C22="",J22="",O22=""),1,0)
A23: =DATE(2025,2,17) | B23: 17 | C23: =Q22 | J23: =IF(COUNTA(D23:I23)>0,SUM(D23:I23),IF(K23="", "", K23)) | O23: =IF(COUNTA(L23:N23)>0,SUM(L23:N23),IF(P23="", "", P23)) | S23: =IF(OR(C23="",J23="",O23=""),"",C23+J23-O23) | W23: =IF(Z23=1,"FALTAN DATOS",IF(S23<0,"OCUPACION NEGATIVA",IF(X23=1,"SOBREOCUPACION",IF(Y23<>0,"BALANCE RARO","OK")))) | X23: =IF(AND(R23<>"",S23>R23),1,0) | Y23: =IF(OR(C23="",J23="",O23="",S23=""),"",C23+J23-O23-S23) | Z23: =IF(OR(R23="",A23="",B23="",C23="",J23="",O23=""),1,0)
A24: =DATE(2025,2,18) | B24: 18 | C24: =Q23 | J24: =IF(COUNTA(D24:I24)>0,SUM(D24:I24),IF(K24="", "", K24)) | O24: =IF(COUNTA(L24:N24)>0,SUM(L24:N24),IF(P24="", "", P24)) | S24: =IF(OR(C24="",J24="",O24=""),"",C24+J24-O24) | W24: =IF(Z24=1,"FALTAN DATOS",IF(S24<0,"OCUPACION NEGATIVA",IF(X24=1,"SOBREOCUPACION",IF(Y24<>0,"BALANCE RARO","OK")))) | X24: =IF(AND(R24<>"",S24>R24),1,0) | Y24: =IF(OR(C24="",J24="",O24="",S24=""),"",C24+J24-O24-S24) | Z24: =IF(OR(R24="",A24="",B24="",C24="",J24="",O24=""),1,0)
A25: =DATE(2025,2,19) | B25: 19 | C25: =Q24 | J25: =IF(COUNTA(D25:I25)>0,SUM(D25:I25),IF(K25="", "", K25)) | O25: =IF(COUNTA(L25:N25)>0,SUM(L25:N25),IF(P25="", "", P25)) | S25: =IF(OR(C25="",J25="",O25=""),"",C25+J25-O25) | W25: =IF(Z25=1,"FALTAN DATOS",IF(S25<0,"OCUPACION NEGATIVA",IF(X25=1,"SOBREOCUPACION",IF(Y25<>0,"BALANCE RARO","OK")))) | X25: =IF(AND(R25<>"",S25>R25),1,0) | Y25: =IF(OR(C25="",J25="",O25="",S25=""),"",C25+J25-O25-S25) | Z25: =IF(OR(R25="",A25="",B25="",C25="",J25="",O25=""),1,0)
A26: =DATE(2025,2,20) | B26: 20 | C26: =Q25 | J26: =IF(COUNTA(D26:I26)>0,SUM(D26:I26),IF(K26="", "", K26)) | O26: =IF(COUNTA(L26:N26)>0,SUM(L26:N26),IF(P26="", "", P26)) | S26: =IF(OR(C26="",J26="",O26=""),"",C26+J26-O26) | W26: =IF(Z26=1,"FALTAN DATOS",IF(S26<0,"OCUPACION NEGATIVA",IF(X26=1,"SOBREOCUPACION",IF(Y26<>0,"BALANCE RARO","OK")))) | X26: =IF(AND(R26<>"",S26>R26),1,0) | Y26: =IF(OR(C26="",J26="",O26="",S26=""),"",C26+J26-O26-S26) | Z26: =IF(OR(R26="",A26="",B26="",C26="",J26="",O26=""),1,0)
A27: =DATE(2025,2,21) | B27: 21 | C27: =Q26 | J27: =IF(COUNTA(D27:I27)>0,SUM(D27:I27),IF(K27="", "", K27)) | O27: =IF(COUNTA(L27:N27)>0,SUM(L27:N27),IF(P27="", "", P27)) | S27: =IF(OR(C27="",J27="",O27=""),"",C27+J27-O27) | W27: =IF(Z27=1,"FALTAN DATOS",IF(S27<0,"OCUPACION NEGATIVA",IF(X27=1,"SOBREOCUPACION",IF(Y27<>0,"BALANCE RARO","OK")))) | X27: =IF(AND(R27<>"",S27>R27),1,0) | Y27: =IF(OR(C27="",J27="",O27="",S27=""),"",C27+J27-O27-S27) | Z27: =IF(OR(R27="",A27="",B27="",C27="",J27="",O27=""),1,0)
A28: =DATE(2025,2,22) | B28: 22 | C28: =Q27 | J28: =IF(COUNTA(D28:I28)>0,SUM(D28:I28),IF(K28="", "", K28)) | O28: =IF(COUNTA(L28:N28)>0,SUM(L28:N28),IF(P28="", "", P28)) | S28: =IF(OR(C28="",J28="",O28=""),"",C28+J28-O28) | W28: =IF(Z28=1,"FALTAN DATOS",IF(S28<0,"OCUPACION NEGATIVA",IF(X28=1,"SOBREOCUPACION",IF(Y28<>0,"BALANCE RARO","OK")))) | X28: =IF(AND(R28<>"",S28>R28),1,0) | Y28: =IF(OR(C28="",J28="",O28="",S28=""),"",C28+J28-O28-S28) | Z28: =IF(OR(R28="",A28="",B28="",C28="",J28="",O28=""),1,0)
A29: =DATE(2025,2,23) | B29: 23 | C29: =Q28 | J29: =IF(COUNTA(D29:I29)>0,SUM(D29:I29),IF(K29="", "", K29)) | O29: =IF(COUNTA(L29:N29)>0,SUM(L29:N29),IF(P29="", "", P29)) | S29: =IF(OR(C29="",J29="",O29=""),"",C29+J29-O29) | W29: =IF(Z29=1,"FALTAN DATOS",IF(S29<0,"OCUPACION NEGATIVA",IF(X29=1,"SOBREOCUPACION",IF(Y29<>0,"BALANCE RARO","OK")))) | X29: =IF(AND(R29<>"",S29>R29),1,0) | Y29: =IF(OR(C29="",J29="",O29="",S29=""),"",C29+J29-O29-S29) | Z29: =IF(OR(R29="",A29="",B29="",C29="",J29="",O29=""),1,0)
A30: =DATE(2025,2,24) | B30: 24 | C30: =Q29 | J30: =IF(COUNTA(D30:I30)>0,SUM(D30:I30),IF(K30="", "", K30)) | O30: =IF(COUNTA(L30:N30)>0,SUM(L30:N30),IF(P30="", "", P30)) | S30: =IF(OR(C30="",J30="",O30=""),"",C30+J30-O30) | W30: =IF(Z30=1,"FALTAN DATOS",IF(S30<0,"OCUPACION NEGATIVA",IF(X30=1,"SOBREOCUPACION",IF(Y30<>0,"BALANCE RARO","OK")))) | X30: =IF(AND(R30<>"",S30>R30),1,0) | Y30: =IF(OR(C30="",J30="",O30="",S30=""),"",C30+J30-O30-S30) | Z30: =IF(OR(R30="",A30="",B30="",C30="",J30="",O30=""),1,0)
A31: =DATE(2025,2,25) | B31: 25 | C31: =Q30 | J31: =IF(COUNTA(D31:I31)>0,SUM(D31:I31),IF(K31="", "", K31)) | O31: =IF(COUNTA(L31:N31)>0,SUM(L31:N31),IF(P31="", "", P31)) | S31: =IF(OR(C31="",J31="",O31=""),"",C31+J31-O31) | W31: =IF(Z31=1,"FALTAN DATOS",IF(S31<0,"OCUPACION NEGATIVA",IF(X31=1,"SOBREOCUPACION",IF(Y31<>0,"BALANCE RARO","OK")))) | X31: =IF(AND(R31<>"",S31>R31),1,0) | Y31: =IF(OR(C31="",J31="",O31="",S31=""),"",C31+J31-O31-S31) | Z31: =IF(OR(R31="",A31="",B31="",C31="",J31="",O31=""),1,0)
A32: =DATE(2025,2,26) | B32: 26 | C32: =Q31 | J32: =IF(COUNTA(D32:I32)>0,SUM(D32:I32),IF(K32="", "", K32)) | O32: =IF(COUNTA(L32:N32)>0,SUM(L32:N32),IF(P32="", "", P32)) | S32: =IF(OR(C32="",J32="",O32=""),"",C32+J32-O32) | W32: =IF(Z32=1,"FALTAN DATOS",IF(S32<0,"OCUPACION NEGATIVA",IF(X32=1,"SOBREOCUPACION",IF(Y32<>0,"BALANCE RARO","OK")))) | X32: =IF(AND(R32<>"",S32>R32),1,0) | Y32: =IF(OR(C32="",J32="",O32="",S32=""),"",C32+J32-O32-S32) | Z32: =IF(OR(R32="",A32="",B32="",C32="",J32="",O32=""),1,0)
A33: =DATE(2025,2,27) | B33: 27 | C33: =Q32 | J33: =IF(COUNTA(D33:I33)>0,SUM(D33:I33),IF(K33="", "", K33)) | O33: =IF(COUNTA(L33:N33)>0,SUM(L33:N33),IF(P33="", "", P33)) | S33: =IF(OR(C33="",J33="",O33=""),"",C33+J33-O33) | W33: =IF(Z33=1,"FALTAN DATOS",IF(S33<0,"OCUPACION NEGATIVA",IF(X33=1,"SOBREOCUPACION",IF(Y33<>0,"BALANCE RARO","OK")))) | X33: =IF(AND(R33<>"",S33>R33),1,0) | Y33: =IF(OR(C33="",J33="",O33="",S33=""),"",C33+J33-O33-S33) | Z33: =IF(OR(R33="",A33="",B33="",C33="",J33="",O33=""),1,0)
A34: =DATE(2025,2,28) | B34: 28 | C34: =Q33 | J34: =IF(COUNTA(D34:I34)>0,SUM(D34:I34),IF(K34="", "", K34)) | O34: =IF(COUNTA(L34:N34)>0,SUM(L34:N34),IF(P34="", "", P34)) | S34: =IF(OR(C34="",J34="",O34=""),"",C34+J34-O34) | W34: =IF(Z34=1,"FALTAN DATOS",IF(S34<0,"OCUPACION NEGATIVA",IF(X34=1,"SOBREOCUPACION",IF(Y34<>0,"BALANCE RARO","OK")))) | X34: =IF(AND(R34<>"",S34>R34),1,0) | Y34: =IF(OR(C34="",J34="",O34="",S34=""),"",C34+J34-O34-S34) | Z34: =IF(OR(R34="",A34="",B34="",C34="",J34="",O34=""),1,0)
A35: TOTAL | D35: =SUM(D7:D34) | E35: =SUM(E7:E34) | F35: =SUM(F7:F34) | G35: =SUM(G7:G34) | H35: =SUM(H7:H34) | I35: =SUM(I7:I34) | J35: =SUM(J7:J34) | K35: =SUM(K7:K34) | ... V35: =SUM(V7:V34)
A38: RESUMEN DEL MES | F38: CONTROL DEL MES
A39: Total ingresos | B39: =J35 | F39: Balance debe ser 0 | G39: =IF(B50=0,"OK","REVISAR")
A40: Total egresos | B40: =O35 | F40: No debe haber ocupacion negativa | G40: =IF(COUNTIF(W7:W34,"OCUPACION NEGATIVA")=0,"OK","REVISAR")
A41: Altas hogar / otro hosp. | B41: =L35 | F41: No deberia faltar existencia inicial | G41: =IF(C7="","REVISAR","OK")
A42: Traslados a otro servicio | B42: =M35 | F42: Dias con alertas | G42: =B52
A43: Fallecidos | B43: =N35
A44: Pacientes atendidos del mes | B44: =C7+J35
A45: Dias personas atendidas | B45: =T35
...

Sheet MARZO 2025
A1: HODOM - MARZO 2025
A2: Servicio | B2: =01_PARAMETROS!B3 | C2: Codigo | D2: =01_PARAMETROS!B4 | E2: Mes | F2: MARZO | G2: Ano | H2: 2025 | I2: Camas base | J2: =01_PARAMETROS!B5 | K2: Dias del mes | L2: 31
A6: Fecha | B6: Dia | C6: Existencia inicial | D6: Ing. urgencia | E6: Ing. hospitalizacion | F6: Ing. ambulatorio | G6: Ing. ley urgencia | H6: Ing. UGCC | I6: Ing. traslado | J6: Total ingresos | K6: Total ingresos informado | L6: Alta hogar / otro hosp. | M6: Traslado a otro servicio | N6: Fallecidos | O6: Total egresos | P6: Total egresos informado | Q6: Ingr.-egr. mismo dia | R6: Camas disponibles | S6: Camas ocupadas | T6: Dias estada total | U6: Dias estada benef. | V6: Observaciones | W6: Estado dia | X6: Check camas | Y6: Check balance | Z6: Check faltantes
A7: =DATE(2025,3,1) | B7: 1 | J7: =IF(COUNTA(D7:I7)>0,SUM(D7:I7),IF(K7="", "", K7)) | O7: =IF(COUNTA(L7:N7)>0,SUM(L7:N7),IF(P7="", "", P7)) | S7: =IF(OR(C7="",J7="",O7=""),"",C7+J7-O7) | W7: =IF(Z7=1,"FALTAN DATOS",IF(S7<0,"OCUPACION NEGATIVA",IF(X7=1,"SOBREOCUPACION",IF(Y7<>0,"BALANCE RARO","OK")))) | X7: =IF(AND(R7<>"",S7>R7),1,0) | Y7: =IF(OR(C7="",J7="",O7="",S7=""),"",C7+J7-O7-S7) | Z7: =IF(OR(R7="",A7="",B7="",C7="",J7="",O7=""),1,0)
A8: =DATE(2025,3,2) | B8: 2 | C8: =Q7 | J8: =IF(COUNTA(D8:I8)>0,SUM(D8:I8),IF(K8="", "", K8)) | O8: =IF(COUNTA(L8:N8)>0,SUM(L8:N8),IF(P8="", "", P8)) | S8: =IF(OR(C8="",J8="",O8=""),"",C8+J8-O8) | W8: =IF(Z8=1,"FALTAN DATOS",IF(S8<0,"OCUPACION NEGATIVA",IF(X8=1,"SOBREOCUPACION",IF(Y8<>0,"BALANCE RARO","OK")))) | X8: =IF(AND(R8<>"",S8>R8),1,0) | Y8: =IF(OR(C8="",J8="",O8="",S8=""),"",C8+J8-O8-S8) | Z8: =IF(OR(R8="",A8="",B8="",C8="",J8="",O8=""),1,0)
A9: =DATE(2025,3,3) | B9: 3 | C9: =Q8 | J9: =IF(COUNTA(D9:I9)>0,SUM(D9:I9),IF(K9="", "", K9)) | O9: =IF(COUNTA(L9:N9)>0,SUM(L9:N9),IF(P9="", "", P9)) | S9: =IF(OR(C9="",J9="",O9=""),"",C9+J9-O9) | W9: =IF(Z9=1,"FALTAN DATOS",IF(S9<0,"OCUPACION NEGATIVA",IF(X9=1,"SOBREOCUPACION",IF(Y9<>0,"BALANCE RARO","OK")))) | X9: =IF(AND(R9<>"",S9>R9),1,0) | Y9: =IF(OR(C9="",J9="",O9="",S9=""),"",C9+J9-O9-S9) | Z9: =IF(OR(R9="",A9="",B9="",C9="",J9="",O9=""),1,0)
A10: =DATE(2025,3,4) | B10: 4 | C10: =Q9 | J10: =IF(COUNTA(D10:I10)>0,SUM(D10:I10),IF(K10="", "", K10)) | O10: =IF(COUNTA(L10:N10)>0,SUM(L10:N10),IF(P10="", "", P10)) | S10: =IF(OR(C10="",J10="",O10=""),"",C10+J10-O10) | W10: =IF(Z10=1,"FALTAN DATOS",IF(S10<0,"OCUPACION NEGATIVA",IF(X10=1,"SOBREOCUPACION",IF(Y10<>0,"BALANCE RARO","OK")))) | X10: =IF(AND(R10<>"",S10>R10),1,0) | Y10: =IF(OR(C10="",J10="",O10="",S10=""),"",C10+J10-O10-S10) | Z10: =IF(OR(R10="",A10="",B10="",C10="",J10="",O10=""),1,0)
A11: =DATE(2025,3,5) | B11: 5 | C11: =Q10 | J11: =IF(COUNTA(D11:I11)>0,SUM(D11:I11),IF(K11="", "", K11)) | O11: =IF(COUNTA(L11:N11)>0,SUM(L11:N11),IF(P11="", "", P11)) | S11: =IF(OR(C11="",J11="",O11=""),"",C11+J11-O11) | W11: =IF(Z11=1,"FALTAN DATOS",IF(S11<0,"OCUPACION NEGATIVA",IF(X11=1,"SOBREOCUPACION",IF(Y11<>0,"BALANCE RARO","OK")))) | X11: =IF(AND(R11<>"",S11>R11),1,0) | Y11: =IF(OR(C11="",J11="",O11="",S11=""),"",C11+J11-O11-S11) | Z11: =IF(OR(R11="",A11="",B11="",C11="",J11="",O11=""),1,0)
A12: =DATE(2025,3,6) | B12: 6 | C12: =Q11 | J12: =IF(COUNTA(D12:I12)>0,SUM(D12:I12),IF(K12="", "", K12)) | O12: =IF(COUNTA(L12:N12)>0,SUM(L12:N12),IF(P12="", "", P12)) | S12: =IF(OR(C12="",J12="",O12=""),"",C12+J12-O12) | W12: =IF(Z12=1,"FALTAN DATOS",IF(S12<0,"OCUPACION NEGATIVA",IF(X12=1,"SOBREOCUPACION",IF(Y12<>0,"BALANCE RARO","OK")))) | X12: =IF(AND(R12<>"",S12>R12),1,0) | Y12: =IF(OR(C12="",J12="",O12="",S12=""),"",C12+J12-O12-S12) | Z12: =IF(OR(R12="",A12="",B12="",C12="",J12="",O12=""),1,0)
A13: =DATE(2025,3,7) | B13: 7 | C13: =Q12 | J13: =IF(COUNTA(D13:I13)>0,SUM(D13:I13),IF(K13="", "", K13)) | O13: =IF(COUNTA(L13:N13)>0,SUM(L13:N13),IF(P13="", "", P13)) | S13: =IF(OR(C13="",J13="",O13=""),"",C13+J13-O13) | W13: =IF(Z13=1,"FALTAN DATOS",IF(S13<0,"OCUPACION NEGATIVA",IF(X13=1,"SOBREOCUPACION",IF(Y13<>0,"BALANCE RARO","OK")))) | X13: =IF(AND(R13<>"",S13>R13),1,0) | Y13: =IF(OR(C13="",J13="",O13="",S13=""),"",C13+J13-O13-S13) | Z13: =IF(OR(R13="",A13="",B13="",C13="",J13="",O13=""),1,0)
A14: =DATE(2025,3,8) | B14: 8 | C14: =Q13 | J14: =IF(COUNTA(D14:I14)>0,SUM(D14:I14),IF(K14="", "", K14)) | O14: =IF(COUNTA(L14:N14)>0,SUM(L14:N14),IF(P14="", "", P14)) | S14: =IF(OR(C14="",J14="",O14=""),"",C14+J14-O14) | W14: =IF(Z14=1,"FALTAN DATOS",IF(S14<0,"OCUPACION NEGATIVA",IF(X14=1,"SOBREOCUPACION",IF(Y14<>0,"BALANCE RARO","OK")))) | X14: =IF(AND(R14<>"",S14>R14),1,0) | Y14: =IF(OR(C14="",J14="",O14="",S14=""),"",C14+J14-O14-S14) | Z14: =IF(OR(R14="",A14="",B14="",C14="",J14="",O14=""),1,0)
A15: =DATE(2025,3,9) | B15: 9 | C15: =Q14 | J15: =IF(COUNTA(D15:I15)>0,SUM(D15:I15),IF(K15="", "", K15)) | O15: =IF(COUNTA(L15:N15)>0,SUM(L15:N15),IF(P15="", "", P15)) | S15: =IF(OR(C15="",J15="",O15=""),"",C15+J15-O15) | W15: =IF(Z15=1,"FALTAN DATOS",IF(S15<0,"OCUPACION NEGATIVA",IF(X15=1,"SOBREOCUPACION",IF(Y15<>0,"BALANCE RARO","OK")))) | X15: =IF(AND(R15<>"",S15>R15),1,0) | Y15: =IF(OR(C15="",J15="",O15="",S15=""),"",C15+J15-O15-S15) | Z15: =IF(OR(R15="",A15="",B15="",C15="",J15="",O15=""),1,0)
A16: =DATE(2025,3,10) | B16: 10 | C16: =Q15 | J16: =IF(COUNTA(D16:I16)>0,SUM(D16:I16),IF(K16="", "", K16)) | O16: =IF(COUNTA(L16:N16)>0,SUM(L16:N16),IF(P16="", "", P16)) | S16: =IF(OR(C16="",J16="",O16=""),"",C16+J16-O16) | W16: =IF(Z16=1,"FALTAN DATOS",IF(S16<0,"OCUPACION NEGATIVA",IF(X16=1,"SOBREOCUPACION",IF(Y16<>0,"BALANCE RARO","OK")))) | X16: =IF(AND(R16<>"",S16>R16),1,0) | Y16: =IF(OR(C16="",J16="",O16="",S16=""),"",C16+J16-O16-S16) | Z16: =IF(OR(R16="",A16="",B16="",C16="",J16="",O16=""),1,0)
A17: =DATE(2025,3,11) | B17: 11 | C17: =Q16 | J17: =IF(COUNTA(D17:I17)>0,SUM(D17:I17),IF(K17="", "", K17)) | O17: =IF(COUNTA(L17:N17)>0,SUM(L17:N17),IF(P17="", "", P17)) | S17: =IF(OR(C17="",J17="",O17=""),"",C17+J17-O17) | W17: =IF(Z17=1,"FALTAN DATOS",IF(S17<0,"OCUPACION NEGATIVA",IF(X17=1,"SOBREOCUPACION",IF(Y17<>0,"BALANCE RARO","OK")))) | X17: =IF(AND(R17<>"",S17>R17),1,0) | Y17: =IF(OR(C17="",J17="",O17="",S17=""),"",C17+J17-O17-S17) | Z17: =IF(OR(R17="",A17="",B17="",C17="",J17="",O17=""),1,0)
A18: =DATE(2025,3,12) | B18: 12 | C18: =Q17 | J18: =IF(COUNTA(D18:I18)>0,SUM(D18:I18),IF(K18="", "", K18)) | O18: =IF(COUNTA(L18:N18)>0,SUM(L18:N18),IF(P18="", "", P18)) | S18: =IF(OR(C18="",J18="",O18=""),"",C18+J18-O18) | W18: =IF(Z18=1,"FALTAN DATOS",IF(S18<0,"OCUPACION NEGATIVA",IF(X18=1,"SOBREOCUPACION",IF(Y18<>0,"BALANCE RARO","OK")))) | X18: =IF(AND(R18<>"",S18>R18),1,0) | Y18: =IF(OR(C18="",J18="",O18="",S18=""),"",C18+J18-O18-S18) | Z18: =IF(OR(R18="",A18="",B18="",C18="",J18="",O18=""),1,0)
A19: =DATE(2025,3,13) | B19: 13 | C19: =Q18 | J19: =IF(COUNTA(D19:I19)>0,SUM(D19:I19),IF(K19="", "", K19)) | O19: =IF(COUNTA(L19:N19)>0,SUM(L19:N19),IF(P19="", "", P19)) | S19: =IF(OR(C19="",J19="",O19=""),"",C19+J19-O19) | W19: =IF(Z19=1,"FALTAN DATOS",IF(S19<0,"OCUPACION NEGATIVA",IF(X19=1,"SOBREOCUPACION",IF(Y19<>0,"BALANCE RARO","OK")))) | X19: =IF(AND(R19<>"",S19>R19),1,0) | Y19: =IF(OR(C19="",J19="",O19="",S19=""),"",C19+J19-O19-S19) | Z19: =IF(OR(R19="",A19="",B19="",C19="",J19="",O19=""),1,0)
