Workbook

Sheet 00_LEEME
A1: HODOM - ESTRUCTURA NUEVA
A3: Objetivo
A4: Dejar una base limpia, simple y consistente para cargar y migrar los meses desde la planilla antigua.
A6: Qué trae este archivo
A7: 1. Una hoja de parámetros generales.
A8: 2. Una hoja mensual estándar por cada mes del período original.
A9: 3. Una hoja de control para revisar rápidamente totales e inconsistencias.
A11: Cómo usarlo
A12: 1. Editar solo celdas amarillas.
A13: 2. No editar celdas verdes: son cálculos.
A14: 3. Revisar alertas en cada hoja mensual y en 99_CONTROL.
A15: 4. Migrar mes por mes desde la planilla antigua.
... A20: Promedio día de estada = días estada total / total egresos.

Sheet 00_PARAMETROS
A1: PARAMETROS GENERALES
A3: Servicio | B3: HODOM
A4: Codigo
A5: Camas base por dia | B5: 16
A6: Responsable
A7: Observaciones

Sheet DICIEMBRE 2024
A1: RESUMEN MENSUAL HODOM | U1: CONTROL
A2: Servicio | B2: =00_PARAMETROS!B3 | C2: Codigo | D2: =00_PARAMETROS!B4 | E2: Mes | F2: DICIEMBRE | G2: Ano | H2: 2024
A3: Camas base | B3: =00_PARAMETROS!B5 | C3: Promedio camas | D3: =AVERAGE(P7:P37) | E3: Dias del mes | F3: 31 | U3: Dias con ocupacion negativa | V3: =COUNTIF(Q7:Q37,"<0")
U4: Dias sin camas disponibles | V4: =COUNTBLANK(P7:P37)
U5: Primer dia sin existencia inicial | V5: =IF(C7="",1,0)
A6: Fecha | B6: Dia | C6: Existencia dia anterior | D6: Ing. urgencia | E6: Ing. hospitalizacion | F6: Ing. ambulatorio | G6: Ing. ley urgencia | H6: Ing. UGCC | I6: Ing. por traslado | J6: Total ingresos | K6: Egr. alta hogar / otro hosp. | L6: Egr. traslado a otro servicio | M6: Egr. fallecidos | N6: Total egresos | O6: Ingr.-egr. mismo dia | P6: Dias cama disponibles | Q6: Dias cama ocupadas | R6: Dias estada total | S6: Dias estada benef. | U6: Dias con total ingresos manualmente alterado | V6: 0
A7: =DATE(2024,12,1) | B7: 1 | J7: =SUM(D7:H7)+I7 | N7: =SUM(K7:M7) | P7: =00_PARAMETROS!B5 | Q7: =C7+J7-N7 | U7: Dias con total egresos manualmente alterado | V7: 0
A8: =DATE(2024,12,2) | B8: 2 | C8: =Q7 | J8: =SUM(D8:H8)+I8 | N8: =SUM(K8:M8) | P8: =00_PARAMETROS!B5 | Q8: =C8+J8-N8
A9: =DATE(2024,12,3) | B9: 3 | C9: =Q8 | J9: =SUM(D9:H9)+I9 | N9: =SUM(K9:M9) | P9: =00_PARAMETROS!B5 | Q9: =C9+J9-N9
A10: =DATE(2024,12,4) | B10: 4 | C10: =Q9 | J10: =SUM(D10:H10)+I10 | N10: =SUM(K10:M10) | P10: =00_PARAMETROS!B5 | Q10: =C10+J10-N10
A11: =DATE(2024,12,5) | B11: 5 | C11: =Q10 | J11: =SUM(D11:H11)+I11 | N11: =SUM(K11:M11) | P11: =00_PARAMETROS!B5 | Q11: =C11+J11-N11
A12: =DATE(2024,12,6) | B12: 6 | C12: =Q11 | J12: =SUM(D12:H12)+I12 | N12: =SUM(K12:M12) | P12: =00_PARAMETROS!B5 | Q12: =C12+J12-N12
A13: =DATE(2024,12,7) | B13: 7 | C13: =Q12 | J13: =SUM(D13:H13)+I13 | N13: =SUM(K13:M13) | P13: =00_PARAMETROS!B5 | Q13: =C13+J13-N13
A14: =DATE(2024,12,8) | B14: 8 | C14: =Q13 | J14: =SUM(D14:H14)+I14 | N14: =SUM(K14:M14) | P14: =00_PARAMETROS!B5 | Q14: =C14+J14-N14
A15: =DATE(2024,12,9) | B15: 9 | C15: =Q14 | J15: =SUM(D15:H15)+I15 | N15: =SUM(K15:M15) | P15: =00_PARAMETROS!B5 | Q15: =C15+J15-N15
A16: =DATE(2024,12,10) | B16: 10 | C16: =Q15 | J16: =SUM(D16:H16)+I16 | N16: =SUM(K16:M16) | P16: =00_PARAMETROS!B5 | Q16: =C16+J16-N16
A17: =DATE(2024,12,11) | B17: 11 | C17: =Q16 | J17: =SUM(D17:H17)+I17 | N17: =SUM(K17:M17) | P17: =00_PARAMETROS!B5 | Q17: =C17+J17-N17
A18: =DATE(2024,12,12) | B18: 12 | C18: =Q17 | J18: =SUM(D18:H18)+I18 | N18: =SUM(K18:M18) | P18: =00_PARAMETROS!B5 | Q18: =C18+J18-N18
A19: =DATE(2024,12,13) | B19: 13 | C19: =Q18 | J19: =SUM(D19:H19)+I19 | N19: =SUM(K19:M19) | P19: =00_PARAMETROS!B5 | Q19: =C19+J19-N19
A20: =DATE(2024,12,14) | B20: 14 | C20: =Q19 | J20: =SUM(D20:H20)+I20 | N20: =SUM(K20:M20) | P20: =00_PARAMETROS!B5 | Q20: =C20+J20-N20
A21: =DATE(2024,12,15) | B21: 15 | C21: =Q20 | J21: =SUM(D21:H21)+I21 | N21: =SUM(K21:M21) | P21: =00_PARAMETROS!B5 | Q21: =C21+J21-N21
A22: =DATE(2024,12,16) | B22: 16 | C22: =Q21 | J22: =SUM(D22:H22)+I22 | N22: =SUM(K22:M22) | P22: =00_PARAMETROS!B5 | Q22: =C22+J22-N22
A23: =DATE(2024,12,17) | B23: 17 | C23: =Q22 | J23: =SUM(D23:H23)+I23 | N23: =SUM(K23:M23) | P23: =00_PARAMETROS!B5 | Q23: =C23+J23-N23
A24: =DATE(2024,12,18) | B24: 18 | C24: =Q23 | J24: =SUM(D24:H24)+I24 | N24: =SUM(K24:M24) | P24: =00_PARAMETROS!B5 | Q24: =C24+J24-N24
A25: =DATE(2024,12,19) | B25: 19 | C25: =Q24 | J25: =SUM(D25:H25)+I25 | N25: =SUM(K25:M25) | P25: =00_PARAMETROS!B5 | Q25: =C25+J25-N25
A26: =DATE(2024,12,20) | B26: 20 | C26: =Q25 | J26: =SUM(D26:H26)+I26 | N26: =SUM(K26:M26) | P26: =00_PARAMETROS!B5 | Q26: =C26+J26-N26
A27: =DATE(2024,12,21) | B27: 21 | C27: =Q26 | J27: =SUM(D27:H27)+I27 | N27: =SUM(K27:M27) | P27: =00_PARAMETROS!B5 | Q27: =C27+J27-N27
A28: =DATE(2024,12,22) | B28: 22 | C28: =Q27 | J28: =SUM(D28:H28)+I28 | N28: =SUM(K28:M28) | P28: =00_PARAMETROS!B5 | Q28: =C28+J28-N28
A29: =DATE(2024,12,23) | B29: 23 | C29: =Q28 | J29: =SUM(D29:H29)+I29 | N29: =SUM(K29:M29) | P29: =00_PARAMETROS!B5 | Q29: =C29+J29-N29
A30: =DATE(2024,12,24) | B30: 24 | C30: =Q29 | J30: =SUM(D30:H30)+I30 | N30: =SUM(K30:M30) | P30: =00_PARAMETROS!B5 | Q30: =C30+J30-N30
A31: =DATE(2024,12,25) | B31: 25 | C31: =Q30 | J31: =SUM(D31:H31)+I31 | N31: =SUM(K31:M31) | P31: =00_PARAMETROS!B5 | Q31: =C31+J31-N31
A32: =DATE(2024,12,26) | B32: 26 | C32: =Q31 | J32: =SUM(D32:H32)+I32 | N32: =SUM(K32:M32) | P32: =00_PARAMETROS!B5 | Q32: =C32+J32-N32
A33: =DATE(2024,12,27) | B33: 27 | C33: =Q32 | J33: =SUM(D33:H33)+I33 | N33: =SUM(K33:M33) | P33: =00_PARAMETROS!B5 | Q33: =C33+J33-N33
A34: =DATE(2024,12,28) | B34: 28 | C34: =Q33 | J34: =SUM(D34:H34)+I34 | N34: =SUM(K34:M34) | P34: =00_PARAMETROS!B5 | Q34: =C34+J34-N34
A35: =DATE(2024,12,29) | B35: 29 | C35: =Q34 | J35: =SUM(D35:H35)+I35 | N35: =SUM(K35:M35) | P35: =00_PARAMETROS!B5 | Q35: =C35+J35-N35
A36: =DATE(2024,12,30) | B36: 30 | C36: =Q35 | J36: =SUM(D36:H36)+I36 | N36: =SUM(K36:M36) | P36: =00_PARAMETROS!B5 | Q36: =C36+J36-N36
A37: =DATE(2024,12,31) | B37: 31 | C37: =Q36 | J37: =SUM(D37:H37)+I37 | N37: =SUM(K37:M37) | P37: =00_PARAMETROS!B5 | Q37: =C37+J37-N37
A38: TOTAL | D38: =SUM(D7:D37) | E38: =SUM(E7:E37) | F38: =SUM(F7:F37) | G38: =SUM(G7:G37) | H38: =SUM(H7:H37) | I38: =SUM(I7:I37) | J38: =SUM(J7:J37) | K38: =SUM(K7:K37) | ... S38: =SUM(S7:S37)
A41: RESUMEN DEL MES
A42: Ingresos | B42: =J38
...

Sheet ENERO 2025
A1: RESUMEN MENSUAL HODOM | U1: CONTROL
A2: Servicio | B2: =00_PARAMETROS!B3 | C2: Codigo | D2: =00_PARAMETROS!B4 | E2: Mes | F2: ENERO | G2: Ano | H2: 2025
A3: Camas base | B3: =00_PARAMETROS!B5 | C3: Promedio camas | D3: =AVERAGE(P7:P37) | E3: Dias del mes | F3: 31 | U3: Dias con ocupacion negativa | V3: =COUNTIF(Q7:Q37,"<0")
U4: Dias sin camas disponibles | V4: =COUNTBLANK(P7:P37)
U5: Primer dia sin existencia inicial | V5: =IF(C7="",1,0)
A6: Fecha | B6: Dia | C6: Existencia dia anterior | D6: Ing. urgencia | E6: Ing. hospitalizacion | F6: Ing. ambulatorio | G6: Ing. ley urgencia | H6: Ing. UGCC | I6: Ing. por traslado | J6: Total ingresos | K6: Egr. alta hogar / otro hosp. | L6: Egr. traslado a otro servicio | M6: Egr. fallecidos | N6: Total egresos | O6: Ingr.-egr. mismo dia | P6: Dias cama disponibles | Q6: Dias cama ocupadas | R6: Dias estada total | S6: Dias estada benef. | U6: Dias con total ingresos manualmente alterado | V6: 0
A7: =DATE(2025,1,1) | B7: 1 | J7: =SUM(D7:H7)+I7 | N7: =SUM(K7:M7) | P7: =00_PARAMETROS!B5 | Q7: =C7+J7-N7 | U7: Dias con total egresos manualmente alterado | V7: 0
A8: =DATE(2025,1,2) | B8: 2 | C8: =Q7 | J8: =SUM(D8:H8)+I8 | N8: =SUM(K8:M8) | P8: =00_PARAMETROS!B5 | Q8: =C8+J8-N8
A9: =DATE(2025,1,3) | B9: 3 | C9: =Q8 | J9: =SUM(D9:H9)+I9 | N9: =SUM(K9:M9) | P9: =00_PARAMETROS!B5 | Q9: =C9+J9-N9
A10: =DATE(2025,1,4) | B10: 4 | C10: =Q9 | J10: =SUM(D10:H10)+I10 | N10: =SUM(K10:M10) | P10: =00_PARAMETROS!B5 | Q10: =C10+J10-N10
A11: =DATE(2025,1,5) | B11: 5 | C11: =Q10 | J11: =SUM(D11:H11)+I11 | N11: =SUM(K11:M11) | P11: =00_PARAMETROS!B5 | Q11: =C11+J11-N11
A12: =DATE(2025,1,6) | B12: 6 | C12: =Q11 | J12: =SUM(D12:H12)+I12 | N12: =SUM(K12:M12) | P12: =00_PARAMETROS!B5 | Q12: =C12+J12-N12
A13: =DATE(2025,1,7) | B13: 7 | C13: =Q12 | J13: =SUM(D13:H13)+I13 | N13: =SUM(K13:M13) | P13: =00_PARAMETROS!B5 | Q13: =C13+J13-N13
A14: =DATE(2025,1,8) | B14: 8 | C14: =Q13 | J14: =SUM(D14:H14)+I14 | N14: =SUM(K14:M14) | P14: =00_PARAMETROS!B5 | Q14: =C14+J14-N14
A15: =DATE(2025,1,9) | B15: 9 | C15: =Q14 | J15: =SUM(D15:H15)+I15 | N15: =SUM(K15:M15) | P15: =00_PARAMETROS!B5 | Q15: =C15+J15-N15
A16: =DATE(2025,1,10) | B16: 10 | C16: =Q15 | J16: =SUM(D16:H16)+I16 | N16: =SUM(K16:M16) | P16: =00_PARAMETROS!B5 | Q16: =C16+J16-N16
A17: =DATE(2025,1,11) | B17: 11 | C17: =Q16 | J17: =SUM(D17:H17)+I17 | N17: =SUM(K17:M17) | P17: =00_PARAMETROS!B5 | Q17: =C17+J17-N17
A18: =DATE(2025,1,12) | B18: 12 | C18: =Q17 | J18: =SUM(D18:H18)+I18 | N18: =SUM(K18:M18) | P18: =00_PARAMETROS!B5 | Q18: =C18+J18-N18
A19: =DATE(2025,1,13) | B19: 13 | C19: =Q18 | J19: =SUM(D19:H19)+I19 | N19: =SUM(K19:M19) | P19: =00_PARAMETROS!B5 | Q19: =C19+J19-N19
A20: =DATE(2025,1,14) | B20: 14 | C20: =Q19 | J20: =SUM(D20:H20)+I20 | N20: =SUM(K20:M20) | P20: =00_PARAMETROS!B5 | Q20: =C20+J20-N20
A21: =DATE(2025,1,15) | B21: 15 | C21: =Q20 | J21: =SUM(D21:H21)+I21 | N21: =SUM(K21:M21) | P21: =00_PARAMETROS!B5 | Q21: =C21+J21-N21
A22: =DATE(2025,1,16) | B22: 16 | C22: =Q21 | J22: =SUM(D22:H22)+I22 | N22: =SUM(K22:M22) | P22: =00_PARAMETROS!B5 | Q22: =C22+J22-N22
A23: =DATE(2025,1,17) | B23: 17 | C23: =Q22 | J23: =SUM(D23:H23)+I23 | N23: =SUM(K23:M23) | P23: =00_PARAMETROS!B5 | Q23: =C23+J23-N23
A24: =DATE(2025,1,18) | B24: 18 | C24: =Q23 | J24: =SUM(D24:H24)+I24 | N24: =SUM(K24:M24) | P24: =00_PARAMETROS!B5 | Q24: =C24+J24-N24
A25: =DATE(2025,1,19) | B25: 19 | C25: =Q24 | J25: =SUM(D25:H25)+I25 | N25: =SUM(K25:M25) | P25: =00_PARAMETROS!B5 | Q25: =C25+J25-N25
A26: =DATE(2025,1,20) | B26: 20 | C26: =Q25 | J26: =SUM(D26:H26)+I26 | N26: =SUM(K26:M26) | P26: =00_PARAMETROS!B5 | Q26: =C26+J26-N26
A27: =DATE(2025,1,21) | B27: 21 | C27: =Q26 | J27: =SUM(D27:H27)+I27 | N27: =SUM(K27:M27) | P27: =00_PARAMETROS!B5 | Q27: =C27+J27-N27
A28: =DATE(2025,1,22) | B28: 22 | C28: =Q27 | J28: =SUM(D28:H28)+I28 | N28: =SUM(K28:M28) | P28: =00_PARAMETROS!B5 | Q28: =C28+J28-N28
A29: =DATE(2025,1,23) | B29: 23 | C29: =Q28 | J29: =SUM(D29:H29)+I29 | N29: =SUM(K29:M29) | P29: =00_PARAMETROS!B5 | Q29: =C29+J29-N29
A30: =DATE(2025,1,24) | B30: 24 | C30: =Q29 | J30: =SUM(D30:H30)+I30 | N30: =SUM(K30:M30) | P30: =00_PARAMETROS!B5 | Q30: =C30+J30-N30
A31: =DATE(2025,1,25) | B31: 25 | C31: =Q30 | J31: =SUM(D31:H31)+I31 | N31: =SUM(K31:M31) | P31: =00_PARAMETROS!B5 | Q31: =C31+J31-N31
A32: =DATE(2025,1,26) | B32: 26 | C32: =Q31 | J32: =SUM(D32:H32)+I32 | N32: =SUM(K32:M32) | P32: =00_PARAMETROS!B5 | Q32: =C32+J32-N32
A33: =DATE(2025,1,27) | B33: 27 | C33: =Q32 | J33: =SUM(D33:H33)+I33 | N33: =SUM(K33:M33) | P33: =00_PARAMETROS!B5 | Q33: =C33+J33-N33
A34: =DATE(2025,1,28) | B34: 28 | C34: =Q33 | J34: =SUM(D34:H34)+I34 | N34: =SUM(K34:M34) | P34: =00_PARAMETROS!B5 | Q34: =C34+J34-N34
A35: =DATE(2025,1,29) | B35: 29 | C35: =Q34 | J35: =SUM(D35:H35)+I35 | N35: =SUM(K35:M35) | P35: =00_PARAMETROS!B5 | Q35: =C35+J35-N35
A36: =DATE(2025,1,30) | B36: 30 | C36: =Q35 | J36: =SUM(D36:H36)+I36 | N36: =SUM(K36:M36) | P36: =00_PARAMETROS!B5 | Q36: =C36+J36-N36
A37: =DATE(2025,1,31) | B37: 31 | C37: =Q36 | J37: =SUM(D37:H37)+I37 | N37: =SUM(K37:M37) | P37: =00_PARAMETROS!B5 | Q37: =C37+J37-N37
A38: TOTAL | D38: =SUM(D7:D37) | E38: =SUM(E7:E37) | F38: =SUM(F7:F37) | G38: =SUM(G7:G37) | H38: =SUM(H7:H37) | I38: =SUM(I7:I37) | J38: =SUM(J7:J37) | K38: =SUM(K7:K37) | ... S38: =SUM(S7:S37)
A41: RESUMEN DEL MES
A42: Ingresos | B42: =J38
...

Sheet FEBRERO 2025
A1: RESUMEN MENSUAL HODOM | U1: CONTROL
A2: Servicio | B2: =00_PARAMETROS!B3 | C2: Codigo | D2: =00_PARAMETROS!B4 | E2: Mes | F2: FEBRERO | G2: Ano | H2: 2025
A3: Camas base | B3: =00_PARAMETROS!B5 | C3: Promedio camas | D3: =AVERAGE(P7:P34) | E3: Dias del mes | F3: 28 | U3: Dias con ocupacion negativa | V3: =COUNTIF(Q7:Q34,"<0")
U4: Dias sin camas disponibles | V4: =COUNTBLANK(P7:P34)
U5: Primer dia sin existencia inicial | V5: =IF(C7="",1,0)
A6: Fecha | B6: Dia | C6: Existencia dia anterior | D6: Ing. urgencia | E6: Ing. hospitalizacion | F6: Ing. ambulatorio | G6: Ing. ley urgencia | H6: Ing. UGCC | I6: Ing. por traslado | J6: Total ingresos | K6: Egr. alta hogar / otro hosp. | L6: Egr. traslado a otro servicio | M6: Egr. fallecidos | N6: Total egresos | O6: Ingr.-egr. mismo dia | P6: Dias cama disponibles | Q6: Dias cama ocupadas | R6: Dias estada total | S6: Dias estada benef. | U6: Dias con total ingresos manualmente alterado | V6: 0
A7: =DATE(2025,2,1) | B7: 1 | J7: =SUM(D7:H7)+I7 | N7: =SUM(K7:M7) | P7: =00_PARAMETROS!B5 | Q7: =C7+J7-N7 | U7: Dias con total egresos manualmente alterado | V7: 0
A8: =DATE(2025,2,2) | B8: 2 | C8: =Q7 | J8: =SUM(D8:H8)+I8 | N8: =SUM(K8:M8) | P8: =00_PARAMETROS!B5 | Q8: =C8+J8-N8
A9: =DATE(2025,2,3) | B9: 3 | C9: =Q8 | J9: =SUM(D9:H9)+I9 | N9: =SUM(K9:M9) | P9: =00_PARAMETROS!B5 | Q9: =C9+J9-N9
A10: =DATE(2025,2,4) | B10: 4 | C10: =Q9 | J10: =SUM(D10:H10)+I10 | N10: =SUM(K10:M10) | P10: =00_PARAMETROS!B5 | Q10: =C10+J10-N10
A11: =DATE(2025,2,5) | B11: 5 | C11: =Q10 | J11: =SUM(D11:H11)+I11 | N11: =SUM(K11:M11) | P11: =00_PARAMETROS!B5 | Q11: =C11+J11-N11
A12: =DATE(2025,2,6) | B12: 6 | C12: =Q11 | J12: =SUM(D12:H12)+I12 | N12: =SUM(K12:M12) | P12: =00_PARAMETROS!B5 | Q12: =C12+J12-N12
A13: =DATE(2025,2,7) | B13: 7 | C13: =Q12 | J13: =SUM(D13:H13)+I13 | N13: =SUM(K13:M13) | P13: =00_PARAMETROS!B5 | Q13: =C13+J13-N13
A14: =DATE(2025,2,8) | B14: 8 | C14: =Q13 | J14: =SUM(D14:H14)+I14 | N14: =SUM(K14:M14) | P14: =00_PARAMETROS!B5 | Q14: =C14+J14-N14
A15: =DATE(2025,2,9) | B15: 9 | C15: =Q14 | J15: =SUM(D15:H15)+I15 | N15: =SUM(K15:M15) | P15: =00_PARAMETROS!B5 | Q15: =C15+J15-N15
A16: =DATE(2025,2,10) | B16: 10 | C16: =Q15 | J16: =SUM(D16:H16)+I16 | N16: =SUM(K16:M16) | P16: =00_PARAMETROS!B5 | Q16: =C16+J16-N16
A17: =DATE(2025,2,11) | B17: 11 | C17: =Q16 | J17: =SUM(D17:H17)+I17 | N17: =SUM(K17:M17) | P17: =00_PARAMETROS!B5 | Q17: =C17+J17-N17
A18: =DATE(2025,2,12) | B18: 12 | C18: =Q17 | J18: =SUM(D18:H18)+I18 | N18: =SUM(K18:M18) | P18: =00_PARAMETROS!B5 | Q18: =C18+J18-N18
A19: =DATE(2025,2,13) | B19: 13 | C19: =Q18 | J19: =SUM(D19:H19)+I19 | N19: =SUM(K19:M19) | P19: =00_PARAMETROS!B5 | Q19: =C19+J19-N19
A20: =DATE(2025,2,14) | B20: 14 | C20: =Q19 | J20: =SUM(D20:H20)+I20 | N20: =SUM(K20:M20) | P20: =00_PARAMETROS!B5 | Q20: =C20+J20-N20
A21: =DATE(2025,2,15) | B21: 15 | C21: =Q20 | J21: =SUM(D21:H21)+I21 | N21: =SUM(K21:M21) | P21: =00_PARAMETROS!B5 | Q21: =C21+J21-N21
A22: =DATE(2025,2,16) | B22: 16 | C22: =Q21 | J22: =SUM(D22:H22)+I22 | N22: =SUM(K22:M22) | P22: =00_PARAMETROS!B5 | Q22: =C22+J22-N22
A23: =DATE(2025,2,17) | B23: 17 | C23: =Q22 | J23: =SUM(D23:H23)+I23 | N23: =SUM(K23:M23) | P23: =00_PARAMETROS!B5 | Q23: =C23+J23-N23
A24: =DATE(2025,2,18) | B24: 18 | C24: =Q23 | J24: =SUM(D24:H24)+I24 | N24: =SUM(K24:M24) | P24: =00_PARAMETROS!B5 | Q24: =C24+J24-N24
A25: =DATE(2025,2,19) | B25: 19 | C25: =Q24 | J25: =SUM(D25:H25)+I25 | N25: =SUM(K25:M25) | P25: =00_PARAMETROS!B5 | Q25: =C25+J25-N25
A26: =DATE(2025,2,20) | B26: 20 | C26: =Q25 | J26: =SUM(D26:H26)+I26 | N26: =SUM(K26:M26) | P26: =00_PARAMETROS!B5 | Q26: =C26+J26-N26
A27: =DATE(2025,2,21) | B27: 21 | C27: =Q26 | J27: =SUM(D27:H27)+I27 | N27: =SUM(K27:M27) | P27: =00_PARAMETROS!B5 | Q27: =C27+J27-N27
A28: =DATE(2025,2,22) | B28: 22 | C28: =Q27 | J28: =SUM(D28:H28)+I28 | N28: =SUM(K28:M28) | P28: =00_PARAMETROS!B5 | Q28: =C28+J28-N28
A29: =DATE(2025,2,23) | B29: 23 | C29: =Q28 | J29: =SUM(D29:H29)+I29 | N29: =SUM(K29:M29) | P29: =00_PARAMETROS!B5 | Q29: =C29+J29-N29
A30: =DATE(2025,2,24) | B30: 24 | C30: =Q29 | J30: =SUM(D30:H30)+I30 | N30: =SUM(K30:M30) | P30: =00_PARAMETROS!B5 | Q30: =C30+J30-N30
A31: =DATE(2025,2,25) | B31: 25 | C31: =Q30 | J31: =SUM(D31:H31)+I31 | N31: =SUM(K31:M31) | P31: =00_PARAMETROS!B5 | Q31: =C31+J31-N31
A32: =DATE(2025,2,26) | B32: 26 | C32: =Q31 | J32: =SUM(D32:H32)+I32 | N32: =SUM(K32:M32) | P32: =00_PARAMETROS!B5 | Q32: =C32+J32-N32
A33: =DATE(2025,2,27) | B33: 27 | C33: =Q32 | J33: =SUM(D33:H33)+I33 | N33: =SUM(K33:M33) | P33: =00_PARAMETROS!B5 | Q33: =C33+J33-N33
A34: =DATE(2025,2,28) | B34: 28 | C34: =Q33 | J34: =SUM(D34:H34)+I34 | N34: =SUM(K34:M34) | P34: =00_PARAMETROS!B5 | Q34: =C34+J34-N34
A35: TOTAL | D35: =SUM(D7:D34) | E35: =SUM(E7:E34) | F35: =SUM(F7:F34) | G35: =SUM(G7:G34) | H35: =SUM(H7:H34) | I35: =SUM(I7:I34) | J35: =SUM(J7:J34) | K35: =SUM(K7:K34) | ... S35: =SUM(S7:S34)
A38: RESUMEN DEL MES
A39: Ingresos | B39: =J35
A40: Altas al hogar / otro hosp. | B40: =K35
A41: Traslados a otro servicio | B41: =L35
A42: Fallecidos | B42: =M35
...

Sheet MARZO 2025
A1: RESUMEN MENSUAL HODOM | U1: CONTROL
A2: Servicio | B2: =00_PARAMETROS!B3 | C2: Codigo | D2: =00_PARAMETROS!B4 | E2: Mes | F2: MARZO | G2: Ano | H2: 2025
A3: Camas base | B3: =00_PARAMETROS!B5 | C3: Promedio camas | D3: =AVERAGE(P7:P37) | E3: Dias del mes | F3: 31 | U3: Dias con ocupacion negativa | V3: =COUNTIF(Q7:Q37,"<0")
U4: Dias sin camas disponibles | V4: =COUNTBLANK(P7:P37)
U5: Primer dia sin existencia inicial | V5: =IF(C7="",1,0)
A6: Fecha | B6: Dia | C6: Existencia dia anterior | D6: Ing. urgencia | E6: Ing. hospitalizacion | F6: Ing. ambulatorio | G6: Ing. ley urgencia | H6: Ing. UGCC | I6: Ing. por traslado | J6: Total ingresos | K6: Egr. alta hogar / otro hosp. | L6: Egr. traslado a otro servicio | M6: Egr. fallecidos | N6: Total egresos | O6: Ingr.-egr. mismo dia | P6: Dias cama disponibles | Q6: Dias cama ocupadas | R6: Dias estada total | S6: Dias estada benef. | U6: Dias con total ingresos manualmente alterado | V6: 0
A7: =DATE(2025,3,1) | B7: 1 | J7: =SUM(D7:H7)+I7 | N7: =SUM(K7:M7) | P7: =00_PARAMETROS!B5 | Q7: =C7+J7-N7 | U7: Dias con total egresos manualmente alterado | V7: 0
A8: =DATE(2025,3,2) | B8: 2 | C8: =Q7 | J8: =SUM(D8:H8)+I8 | N8: =SUM(K8:M8) | P8: =00_PARAMETROS!B5 | Q8: =C8+J8-N8
A9: =DATE(2025,3,3) | B9: 3 | C9: =Q8 | J9: =SUM(D9:H9)+I9 | N9: =SUM(K9:M9) | P9: =00_PARAMETROS!B5 | Q9: =C9+J9-N9
A10: =DATE(2025,3,4) | B10: 4 | C10: =Q9 | J10: =SUM(D10:H10)+I10 | N10: =SUM(K10:M10) | P10: =00_PARAMETROS!B5 | Q10: =C10+J10-N10
A11: =DATE(2025,3,5) | B11: 5 | C11: =Q10 | J11: =SUM(D11:H11)+I11 | N11: =SUM(K11:M11) | P11: =00_PARAMETROS!B5 | Q11: =C11+J11-N11
A12: =DATE(2025,3,6) | B12: 6 | C12: =Q11 | J12: =SUM(D12:H12)+I12 | N12: =SUM(K12:M12) | P12: =00_PARAMETROS!B5 | Q12: =C12+J12-N12
A13: =DATE(2025,3,7) | B13: 7 | C13: =Q12 | J13: =SUM(D13:H13)+I13 | N13: =SUM(K13:M13) | P13: =00_PARAMETROS!B5 | Q13: =C13+J13-N13
A14: =DATE(2025,3,8) | B14: 8 | C14: =Q13 | J14: =SUM(D14:H14)+I14 | N14: =SUM(K14:M14) | P14: =00_PARAMETROS!B5 | Q14: =C14+J14-N14
A15: =DATE(2025,3,9) | B15: 9 | C15: =Q14 | J15: =SUM(D15:H15)+I15 | N15: =SUM(K15:M15) | P15: =00_PARAMETROS!B5 | Q15: =C15+J15-N15
A16: =DATE(2025,3,10) | B16: 10 | C16: =Q15 | J16: =SUM(D16:H16)+I16 | N16: =SUM(K16:M16) | P16: =00_PARAMETROS!B5 | Q16: =C16+J16-N16
A17: =DATE(2025,3,11) | B17: 11 | C17: =Q16 | J17: =SUM(D17:H17)+I17 | N17: =SUM(K17:M17) | P17: =00_PARAMETROS!B5 | Q17: =C17+J17-N17
A18: =DATE(2025,3,12) | B18: 12 | C18: =Q17 | J18: =SUM(D18:H18)+I18 | N18: =SUM(K18:M18) | P18: =00_PARAMETROS!B5 | Q18: =C18+J18-N18
A19: =DATE(2025,3,13) | B19: 13 | C19: =Q18 | J19: =SUM(D19:H19)+I19 | N19: =SUM(K19:M19) | P19: =00_PARAMETROS!B5 | Q19: =C19+J19-N19
A20: =DATE(2025,3,14) | B20: 14 | C20: =Q19 | J20: =SUM(D20:H20)+I20 | N20: =SUM(K20:M20) | P20: =00_PARAMETROS!B5 | Q20: =C20+J20-N20
A21: =DATE(2025,3,15) | B21: 15 | C21: =Q20 | J21: =SUM(D21:H21)+I21 | N21: =SUM(K21:M21) | P21: =00_PARAMETROS!B5 | Q21: =C21+J21-N21
A22: =DATE(2025,3,16) | B22: 16 | C22: =Q21 | J22: =SUM(D22:H22)+I22 | N22: =SUM(K22:M22) | P22: =00_PARAMETROS!B5 | Q22: =C22+J22-N22
A23: =DATE(2025,3,17) | B23: 17 | C23: =Q22 | J23: =SUM(D23:H23)+I23 | N23: =SUM(K23:M23) | P23: =00_PARAMETROS!B5 | Q23: =C23+J23-N23
A24: =DATE(2025,3,18) | B24: 18 | C24: =Q23 | J24: =SUM(D24:H24)+I24 | N24: =SUM(K24:M24) | P24: =00_PARAMETROS!B5 | Q24: =C24+J24-N24
A25: =DATE(2025,3,19) | B25: 19 | C25: =Q24 | J25: =SUM(D25:H25)+I25 | N25: =SUM(K25:M25) | P25: =00_PARAMETROS!B5 | Q25: =C25+J25-N25
A26: =DATE(2025,3,20) | B26: 20 | C26: =Q25 | J26: =SUM(D26:H26)+I26 | N26: =SUM(K26:M26) | P26: =00_PARAMETROS!B5 | Q26: =C26+J26-N26
A27: =DATE(2025,3,21) | B27: 21 | C27: =Q26 | J27: =SUM(D27:H27)+I27 | N27: =SUM(K27:M27) | P27: =00_PARAMETROS!B5 | Q27: =C27+J27-N27
A28: =DATE(2025,3,22) | B28: 22 | C28: =Q27 | J28: =SUM(D28:H28)+I28 | N28: =SUM(K28:M28) | P28: =00_PARAMETROS!B5 | Q28: =C28+J28-N28
A29: =DATE(2025,3,23) | B29: 23 | C29: =Q28 | J29: =SUM(D29:H29)+I29 | N29: =SUM(K29:M29) | P29: =00_PARAMETROS!B5 | Q29: =C29+J29-N29
A30: =DATE(2025,3,24) | B30: 24 | C30: =Q29 | J30: =SUM(D30:H30)+I30 | N30: =SUM(K30:M30) | P30: =00_PARAMETROS!B5 | Q30: =C30+J30-N30
A31: =DATE(2025,3,25) | B31: 25 | C31: =Q30 | J31: =SUM(D31:H31)+I31 | N31: =SUM(K31:M31) | P31: =00_PARAMETROS!B5 | Q31: =C31+J31-N31
A32: =DATE(2025,3,26) | B32: 26 | C32: =Q31 | J32: =SUM(D32:H32)+I32 | N32: =SUM(K32:M32) | P32: =00_PARAMETROS!B5 | Q32: =C32+J32-N32
A33: =DATE(2025,3,27) | B33: 27 | C33: =Q32 | J33: =SUM(D33:H33)+I33 | N33: =SUM(K33:M33) | P33: =00_PARAMETROS!B5 | Q33: =C33+J33-N33
A34: =DATE(2025,3,28) | B34: 28 | C34: =Q33 | J34: =SUM(D34:H34)+I34 | N34: =SUM(K34:M34) | P34: =00_PARAMETROS!B5 | Q34: =C34+J34-N34
A35: =DATE(2025,3,29) | B35: 29 | C35: =Q34 | J35: =SUM(D35:H35)+I35 | N35: =SUM(K35:M35) | P35: =00_PARAMETROS!B5 | Q35: =C35+J35-N35
A36: =DATE(2025,3,30) | B36: 30 | C36: =Q35 | J36: =SUM(D36:H36)+I36 | N36: =SUM(K36:M36) | P36: =00_PARAMETROS!B5 | Q36: =C36+J36-N36
A37: =DATE(2025,3,31) | B37: 31 | C37: =Q36 | J37: =SUM(D37:H37)+I37 | N37: =SUM(K37:M37) | P37: =00_PARAMETROS!B5 | Q37: =C37+J37-N37
A38: TOTAL | D38: =SUM(D7:D37) | E38: =SUM(E7:E37) | F38: =SUM(F7:F37) | G38: =SUM(G7:G37) | H38: =SUM(H7:H37) | I38: =SUM(I7:I37) | J38: =SUM(J7:J37) | K38: =SUM(K7:K37) | ... S38: =SUM(S7:S37)
A41: RESUMEN DEL MES
A42: Ingresos | B42: =J38
...

Sheet ABRIL 2025
A1: RESUMEN MENSUAL HODOM | U1: CONTROL
A2: Servicio | B2: =00_PARAMETROS!B3 | C2: Codigo | D2: =00_PARAMETROS!B4 | E2: Mes | F2: ABRIL | G2: Ano | H2: 2025
A3: Camas base | B3: =00_PARAMETROS!B5 | C3: Promedio camas | D3: =AVERAGE(P7:P36) | E3: Dias del mes | F3: 30 | U3: Dias con ocupacion negativa | V3: =COUNTIF(Q7:Q36,"<0")
U4: Dias sin camas disponibles | V4: =COUNTBLANK(P7:P36)
U5: Primer dia sin existencia inicial | V5: =IF(C7="",1,0)
A6: Fecha | B6: Dia | C6: Existencia dia anterior | D6: Ing. urgencia | E6: Ing. hospitalizacion | F6: Ing. ambulatorio | G6: Ing. ley urgencia | H6: Ing. UGCC | I6: Ing. por traslado | J6: Total ingresos | K6: Egr. alta hogar / otro hosp. | L6: Egr. traslado a otro servicio | M6: Egr. fallecidos | N6: Total egresos | O6: Ingr.-egr. mismo dia | P6: Dias cama disponibles | Q6: Dias cama ocupadas | R6: Dias estada total | S6: Dias estada benef. | U6: Dias con total ingresos manualmente alterado | V6: 0
A7: =DATE(2025,4,1) | B7: 1 | J7: =SUM(D7:H7)+I7 | N7: =SUM(K7:M7) | P7: =00_PARAMETROS!B5 | Q7: =C7+J7-N7 | U7: Dias con total egresos manualmente alterado | V7: 0
A8: =DATE(2025,4,2) | B8: 2 | C8: =Q7 | J8: =SUM(D8:H8)+I8 | N8: =SUM(K8:M8) | P8: =00_PARAMETROS!B5 | Q8: =C8+J8-N8
A9: =DATE(2025,4,3) | B9: 3 | C9: =Q8 | J9: =SUM(D9:H9)+I9 | N9: =SUM(K9:M9) | P9: =00_PARAMETROS!B5 | Q9: =C9+J9-N9
A10: =DATE(2025,4,4) | B10: 4 | C10: =Q9 | J10: =SUM(D10:H10)+I10 | N10: =SUM(K10:M10) | P10: =00_PARAMETROS!B5 | Q10: =C10+J10-N10
A11: =DATE(2025,4,5) | B11: 5 | C11: =Q10 | J11: =SUM(D11:H11)+I11 | N11: =SUM(K11:M11) | P11: =00_PARAMETROS!B5 | Q11: =C11+J11-N11
A12: =DATE(2025,4,6) | B12: 6 | C12: =Q11 | J12: =SUM(D12:H12)+I12 | N12: =SUM(K12:M12) | P12: =00_PARAMETROS!B5 | Q12: =C12+J12-N12
A13: =DATE(2025,4,7) | B13: 7 | C13: =Q12 | J13: =SUM(D13:H13)+I13 | N13: =SUM(K13:M13) | P13: =00_PARAMETROS!B5 | Q13: =C13+J13-N13
A14: =DATE(2025,4,8) | B14: 8 | C14: =Q13 | J14: =SUM(D14:H14)+I14 | N14: =SUM(K14:M14) | P14: =00_PARAMETROS!B5 | Q14: =C14+J14-N14
A15: =DATE(2025,4,9) | B15: 9 | C15: =Q14 | J15: =SUM(D15:H15)+I15 | N15: =SUM(K15:M15) | P15: =00_PARAMETROS!B5 | Q15: =C15+J15-N15
A16: =DATE(2025,4,10) | B16: 10 | C16: =Q15 | J16: =SUM(D16:H16)+I16 | N16: =SUM(K16:M16) | P16: =00_PARAMETROS!B5 | Q16: =C16+J16-N16
A17: =DATE(2025,4,11) | B17: 11 | C17: =Q16 | J17: =SUM(D17:H17)+I17 | N17: =SUM(K17:M17) | P17: =00_PARAMETROS!B5 | Q17: =C17+J17-N17
A18: =DATE(2025,4,12) | B18: 12 | C18: =Q17 | J18: =SUM(D18:H18)+I18 | N18: =SUM(K18:M18) | P18: =00_PARAMETROS!B5 | Q18: =C18+J18-N18
A19: =DATE(2025,4,13) | B19: 13 | C19: =Q18 | J19: =SUM(D19:H19)+I19 | N19: =SUM(K19:M19) | P19: =00_PARAMETROS!B5 | Q19: =C19+J19-N19
A20: =DATE(2025,4,14) | B20: 14 | C20: =Q19 | J20: =SUM(D20:H20)+I20 | N20: =SUM(K20:M20) | P20: =00_PARAMETROS!B5 | Q20: =C20+J20-N20
A21: =DATE(2025,4,15) | B21: 15 | C21: =Q20 | J21: =SUM(D21:H21)+I21 | N21: =SUM(K21:M21) | P21: =00_PARAMETROS!B5 | Q21: =C21+J21-N21
A22: =DATE(2025,4,16) | B22: 16 | C22: =Q21 | J22: =SUM(D22:H22)+I22 | N22: =SUM(K22:M22) | P22: =00_PARAMETROS!B5 | Q22: =C22+J22-N22
A23: =DATE(2025,4,17) | B23: 17 | C23: =Q22 | J23: =SUM(D23:H23)+I23 | N23: =SUM(K23:M23) | P23: =00_PARAMETROS!B5 | Q23: =C23+J23-N23
A24: =DATE(2025,4,18) | B24: 18 | C24: =Q23 | J24: =SUM(D24:H24)+I24 | N24: =SUM(K24:M24) | P24: =00_PARAMETROS!B5 | Q24: =C24+J24-N24
A25: =DATE(2025,4,19) | B25: 19 | C25: =Q24 | J25: =SUM(D25:H25)+I25 | N25: =SUM(K25:M25) | P25: =00_PARAMETROS!B5 | Q25: =C25+J25-N25
A26: =DATE(2025,4,20) | B26: 20 | C26: =Q25 | J26: =SUM(D26:H26)+I26 | N26: =SUM(K26:M26) | P26: =00_PARAMETROS!B5 | Q26: =C26+J26-N26
A27: =DATE(2025,4,21) | B27: 21 | C27: =Q26 | J27: =SUM(D27:H27)+I27 | N27: =SUM(K27:M27) | P27: =00_PARAMETROS!B5 | Q27: =C27+J27-N27
A28: =DATE(2025,4,22) | B28: 22 | C28: =Q27 | J28: =SUM(D28:H28)+I28 | N28: =SUM(K28:M28) | P28: =00_PARAMETROS!B5 | Q28: =C28+J28-N28
A29: =DATE(2025,4,23) | B29: 23 | C29: =Q28 | J29: =SUM(D29:H29)+I29 | N29: =SUM(K29:M29) | P29: =00_PARAMETROS!B5 | Q29: =C29+J29-N29
A30: =DATE(2025,4,24) | B30: 24 | C30: =Q29 | J30: =SUM(D30:H30)+I30 | N30: =SUM(K30:M30) | P30: =00_PARAMETROS!B5 | Q30: =C30+J30-N30
A31: =DATE(2025,4,25) | B31: 25 | C31: =Q30 | J31: =SUM(D31:H31)+I31 | N31: =SUM(K31:M31) | P31: =00_PARAMETROS!B5 | Q31: =C31+J31-N31
A32: =DATE(2025,4,26) | B32: 26 | C32: =Q31 | J32: =SUM(D32:H32)+I32 | N32: =SUM(K32:M32) | P32: =00_PARAMETROS!B5 | Q32: =C32+J32-N32
A33: =DATE(2025,4,27) | B33: 27 | C33: =Q32 | J33: =SUM(D33:H33)+I33 | N33: =SUM(K33:M33) | P33: =00_PARAMETROS!B5 | Q33: =C33+J33-N33
A34: =DATE(2025,4,28) | B34: 28 | C34: =Q33 | J34: =SUM(D34:H34)+I34 | N34: =SUM(K34:M34) | P34: =00_PARAMETROS!B5 | Q34: =C34+J34-N34
A35: =DATE(2025,4,29) | B35: 29 | C35: =Q34 | J35: =SUM(D35:H35)+I35 | N35: =SUM(K35:M35) | P35: =00_PARAMETROS!B5 | Q35: =C35+J35-N35
A36: =DATE(2025,4,30) | B36: 30 | C36: =Q35 | J36: =SUM(D36:H36)+I36 | N36: =SUM(K36:M36) | P36: =00_PARAMETROS!B5 | Q36: =C36+J36-N36
A37: TOTAL | D37: =SUM(D7:D36) | E37: =SUM(E7:E36) | F37: =SUM(F7:F36) | G37: =SUM(G7:G36) | H37: =SUM(H7:H36) | I37: =SUM(I7:I36) | J37: =SUM(J7:J36) | K37: =SUM(K7:K36) | ... S37: =SUM(S7:S36)
A40: RESUMEN DEL MES
A41: Ingresos | B41: =J37
A42: Altas al hogar / otro hosp. | B42: =K37
...

Sheet MAYO 2025
A1: RESUMEN MENSUAL HODOM | U1: CONTROL
A2: Servicio | B2: =00_PARAMETROS!B3 | C2: Codigo | D2: =00_PARAMETROS!B4 | E2: Mes | F2: MAYO | G2: Ano | H2: 2025
A3: Camas base | B3: =00_PARAMETROS!B5 | C3: Promedio camas | D3: =AVERAGE(P7:P37) | E3: Dias del mes | F3: 31 | U3: Dias con ocupacion negativa | V3: =COUNTIF(Q7:Q37,"<0")
U4: Dias sin camas disponibles | V4: =COUNTBLANK(P7:P37)
U5: Primer dia sin existencia inicial | V5: =IF(C7="",1,0)
A6: Fecha | B6: Dia | C6: Existencia dia anterior | D6: Ing. urgencia | E6: Ing. hospitalizacion | F6: Ing. ambulatorio | G6: Ing. ley urgencia | H6: Ing. UGCC | I6: Ing. por traslado | J6: Total ingresos | K6: Egr. alta hogar / otro hosp. | L6: Egr. traslado a otro servicio | M6: Egr. fallecidos | N6: Total egresos | O6: Ingr.-egr. mismo dia | P6: Dias cama disponibles | Q6: Dias cama ocupadas | R6: Dias estada total | S6: Dias estada benef. | U6: Dias con total ingresos manualmente alterado | V6: 0
A7: =DATE(2025,5,1) | B7: 1 | J7: =SUM(D7:H7)+I7 | N7: =SUM(K7:M7) | P7: =00_PARAMETROS!B5 | Q7: =C7+J7-N7 | U7: Dias con total egresos manualmente alterado | V7: 0
A8: =DATE(2025,5,2) | B8: 2 | C8: =Q7 | J8: =SUM(D8:H8)+I8 | N8: =SUM(K8:M8) | P8: =00_PARAMETROS!B5 | Q8: =C8+J8-N8
A9: =DATE(2025,5,3) | B9: 3 | C9: =Q8 | J9: =SUM(D9:H9)+I9 | N9: =SUM(K9:M9) | P9: =00_PARAMETROS!B5 | Q9: =C9+J9-N9
A10: =DATE(2025,5,4) | B10: 4 | C10: =Q9 | J10: =SUM(D10:H10)+I10 | N10: =SUM(K10:M10) | P10: =00_PARAMETROS!B5 | Q10: =C10+J10-N10
A11: =DATE(2025,5,5) | B11: 5 | C11: =Q10 | J11: =SUM(D11:H11)+I11 | N11: =SUM(K11:M11) | P11: =00_PARAMETROS!B5 | Q11: =C11+J11-N11
A12: =DATE(2025,5,6) | B12: 6 | C12: =Q11 | J12: =SUM(D12:H12)+I12 | N12: =SUM(K12:M12) | P12: =00_PARAMETROS!B5 | Q12: =C12+J12-N12
A13: =DATE(2025,5,7) | B13: 7 | C13: =Q12 | J13: =SUM(D13:H13)+I13 | N13: =SUM(K13:M13) | P13: =00_PARAMETROS!B5 | Q13: =C13+J13-N13
A14: =DATE(2025,5,8) | B14: 8 | C14: =Q13 | J14: =SUM(D14:H14)+I14 | N14: =SUM(K14:M14) | P14: =00_PARAMETROS!B5 | Q14: =C14+J14-N14
A15: =DATE(2025,5,9) | B15: 9 | C15: =Q14 | J15: =SUM(D15:H15)+I15 | N15: =SUM(K15:M15) | P15: =00_PARAMETROS!B5 | Q15: =C15+J15-N15
A16: =DATE(2025,5,10) | B16: 10 | C16: =Q15 | J16: =SUM(D16:H16)+I16 | N16: =SUM(K16:M16) | P16: =00_PARAMETROS!B5 | Q16: =C16+J16-N16
A17: =DATE(2025,5,11) | B17: 11 | C17: =Q16 | J17: =SUM(D17:H17)+I17 | N17: =SUM(K17:M17) | P17: =00_PARAMETROS!B5 | Q17: =C17+J17-N17
A18: =DATE(2025,5,12) | B18: 12 | C18: =Q17 | J18: =SUM(D18:H18)+I18 | N18: =SUM(K18:M18) | P18: =00_PARAMETROS!B5 | Q18: =C18+J18-N18
A19: =DATE(2025,5,13) | B19: 13 | C19: =Q18 | J19: =SUM(D19:H19)+I19 | N19: =SUM(K19:M19) | P19: =00_PARAMETROS!B5 | Q19: =C19+J19-N19
A20: =DATE(2025,5,14) | B20: 14 | C20: =Q19 | J20: =SUM(D20:H20)+I20 | N20: =SUM(K20:M20) | P20: =00_PARAMETROS!B5 | Q20: =C20+J20-N20
A21: =DATE(2025,5,15) | B21: 15 | C21: =Q20 | J21: =SUM(D21:H21)+I21 | N21: =SUM(K21:M21) | P21: =00_PARAMETROS!B5 | Q21: =C21+J21-N21
A22: =DATE(2025,5,16) | B22: 16 | C22: =Q21 | J22: =SUM(D22:H22)+I22 | N22: =SUM(K22:M22) | P22: =00_PARAMETROS!B5 | Q22: =C22+J22-N22
A23: =DATE(2025,5,17) | B23: 17 | C23: =Q22 | J23: =SUM(D23:H23)+I23 | N23: =SUM(K23:M23) | P23: =00_PARAMETROS!B5 | Q23: =C23+J23-N23
A24: =DATE(2025,5,18) | B24: 18 | C24: =Q23 | J24: =SUM(D24:H24)+I24 | N24: =SUM(K24:M24) | P24: =00_PARAMETROS!B5 | Q24: =C24+J24-N24
A25: =DATE(2025,5,19) | B25: 19 | C25: =Q24 | J25: =SUM(D25:H25)+I25 | N25: =SUM(K25:M25) | P25: =00_PARAMETROS!B5 | Q25: =C25+J25-N25
A26: =DATE(2025,5,20) | B26: 20 | C26: =Q25 | J26: =SUM(D26:H26)+I26 | N26: =SUM(K26:M26) | P26: =00_PARAMETROS!B5 | Q26: =C26+J26-N26
A27: =DATE(2025,5,21) | B27: 21 | C27: =Q26 | J27: =SUM(D27:H27)+I27 | N27: =SUM(K27:M27) | P27: =00_PARAMETROS!B5 | Q27: =C27+J27-N27
A28: =DATE(2025,5,22) | B28: 22 | C28: =Q27 | J28: =SUM(D28:H28)+I28 | N28: =SUM(K28:M28) | P28: =00_PARAMETROS!B5 | Q28: =C28+J28-N28
A29: =DATE(2025,5,23) | B29: 23 | C29: =Q28 | J29: =SUM(D29:H29)+I29 | N29: =SUM(K29:M29) | P29: =00_PARAMETROS!B5 | Q29: =C29+J29-N29
A30: =DATE(2025,5,24) | B30: 24 | C30: =Q29 | J30: =SUM(D30:H30)+I30 | N30: =SUM(K30:M30) | P30: =00_PARAMETROS!B5 | Q30: =C30+J30-N30
A31: =DATE(2025,5,25) | B31: 25 | C31: =Q30 | J31: =SUM(D31:H31)+I31 | N31: =SUM(K31:M31) | P31: =00_PARAMETROS!B5 | Q31: =C31+J31-N31
A32: =DATE(2025,5,26) | B32: 26 | C32: =Q31 | J32: =SUM(D32:H32)+I32 | N32: =SUM(K32:M32) | P32: =00_PARAMETROS!B5 | Q32: =C32+J32-N32
A33: =DATE(2025,5,27) | B33: 27 | C33: =Q32 | J33: =SUM(D33:H33)+I33 | N33: =SUM(K33:M33) | P33: =00_PARAMETROS!B5 | Q33: =C33+J33-N33
A34: =DATE(2025,5,28) | B34: 28 | C34: =Q33 | J34: =SUM(D34:H34)+I34 | N34: =SUM(K34:M34) | P34: =00_PARAMETROS!B5 | Q34: =C34+J34-N34
A35: =DATE(2025,5,29) | B35: 29 | C35: =Q34 | J35: =SUM(D35:H35)+I35 | N35: =SUM(K35:M35) | P35: =00_PARAMETROS!B5 | Q35: =C35+J35-N35
A36: =DATE(2025,5,30) | B36: 30 | C36: =Q35 | J36: =SUM(D36:H36)+I36 | N36: =SUM(K36:M36) | P36: =00_PARAMETROS!B5 | Q36: =C36+J36-N36
A37: =DATE(2025,5,31) | B37: 31 | C37: =Q36 | J37: =SUM(D37:H37)+I37 | N37: =SUM(K37:M37) | P37: =00_PARAMETROS!B5 | Q37: =C37+J37-N37
A38: TOTAL | D38: =SUM(D7:D37) | E38: =SUM(E7:E37) | F38: =SUM(F7:F37) | G38: =SUM(G7:G37) | H38: =SUM(H7:H37) | I38: =SUM(I7:I37) | J38: =SUM(J7:J37) | K38: =SUM(K7:K37) | ... S38: =SUM(S7:S37)
A41: RESUMEN DEL MES
A42: Ingresos | B42: =J38
...

Sheet JUNIO 2025
A1: RESUMEN MENSUAL HODOM | U1: CONTROL
A2: Servicio | B2: =00_PARAMETROS!B3 | C2: Codigo | D2: =00_PARAMETROS!B4 | E2: Mes | F2: JUNIO | G2: Ano | H2: 2025
A3: Camas base | B3: =00_PARAMETROS!B5 | C3: Promedio camas | D3: =AVERAGE(P7:P36) | E3: Dias del mes | F3: 30 | U3: Dias con ocupacion negativa | V3: =COUNTIF(Q7:Q36,"<0")
U4: Dias sin camas disponibles | V4: =COUNTBLANK(P7:P36)
U5: Primer dia sin existencia inicial | V5: =IF(C7="",1,0)
A6: Fecha | B6: Dia | C6: Existencia dia anterior | D6: Ing. urgencia | E6: Ing. hospitalizacion | F6: Ing. ambulatorio | G6: Ing. ley urgencia | H6: Ing. UGCC | I6: Ing. por traslado | J6: Total ingresos | K6: Egr. alta hogar / otro hosp. | L6: Egr. traslado a otro servicio | M6: Egr. fallecidos | N6: Total egresos | O6: Ingr.-egr. mismo dia | P6: Dias cama disponibles | Q6: Dias cama ocupadas | R6: Dias estada total | S6: Dias estada benef. | U6: Dias con total ingresos manualmente alterado | V6: 0
A7: =DATE(2025,6,1) | B7: 1 | J7: =SUM(D7:H7)+I7 | N7: =SUM(K7:M7) | P7: =00_PARAMETROS!B5 | Q7: =C7+J7-N7 | U7: Dias con total egresos manualmente alterado | V7: 0
A8: =DATE(2025,6,2) | B8: 2 | C8: =Q7 | J8: =SUM(D8:H8)+I8 | N8: =SUM(K8:M8) | P8: =00_PARAMETROS!B5 | Q8: =C8+J8-N8
A9: =DATE(2025,6,3) | B9: 3 | C9: =Q8 | J9: =SUM(D9:H9)+I9 | N9: =SUM(K9:M9) | P9: =00_PARAMETROS!B5 | Q9: =C9+J9-N9
A10: =DATE(2025,6,4) | B10: 4 | C10: =Q9 | J10: =SUM(D10:H10)+I10 | N10: =SUM(K10:M10) | P10: =00_PARAMETROS!B5 | Q10: =C10+J10-N10
A11: =DATE(2025,6,5) | B11: 5 | C11: =Q10 | J11: =SUM(D11:H11)+I11 | N11: =SUM(K11:M11) | P11: =00_PARAMETROS!B5 | Q11: =C11+J11-N11
A12: =DATE(2025,6,6) | B12: 6 | C12: =Q11 | J12: =SUM(D12:H12)+I12 | N12: =SUM(K12:M12) | P12: =00_PARAMETROS!B5 | Q12: =C12+J12-N12
A13: =DATE(2025,6,7) | B13: 7 | C13: =Q12 | J13: =SUM(D13:H13)+I13 | N13: =SUM(K13:M13) | P13: =00_PARAMETROS!B5 | Q13: =C13+J13-N13
A14: =DATE(2025,6,8) | B14: 8 | C14: =Q13 | J14: =SUM(D14:H14)+I14 | N14: =SUM(K14:M14) | P14: =00_PARAMETROS!B5 | Q14: =C14+J14-N14
A15: =DATE(2025,6,9) | B15: 9 | C15: =Q14 | J15: =SUM(D15:H15)+I15 | N15: =SUM(K15:M15) | P15: =00_PARAMETROS!B5 | Q15: =C15+J15-N15
A16: =DATE(2025,6,10) | B16: 10 | C16: =Q15 | J16: =SUM(D16:H16)+I16 | N16: =SUM(K16:M16) | P16: =00_PARAMETROS!B5 | Q16: =C16+J16-N16
A17: =DATE(2025,6,11) | B17: 11 | C17: =Q16 | J17: =SUM(D17:H17)+I17 | N17: =SUM(K17:M17) | P17: =00_PARAMETROS!B5 | Q17: =C17+J17-N17
A18: =DATE(2025,6,12) | B18: 12 | C18: =Q17 | J18: =SUM(D18:H18)+I18 | N18: =SUM(K18:M18) | P18: =00_PARAMETROS!B5 | Q18: =C18+J18-N18
A19: =DATE(2025,6,13) | B19: 13 | C19: =Q18 | J19: =SUM(D19:H19)+I19 | N19: =SUM(K19:M19) | P19: =00_PARAMETROS!B5 | Q19: =C19+J19-N19
A20: =DATE(2025,6,14) | B20: 14 | C20: =Q19 | J20: =SUM(D20:H20)+I20 | N20: =SUM(K20:M20) | P20: =00_PARAMETROS!B5 | Q20: =C20+J20-N20
A21: =DATE(2025,6,15) | B21: 15 | C21: =Q20 | J21: =SUM(D21:H21)+I21 | N21: =SUM(K21:M21) | P21: =00_PARAMETROS!B5 | Q21: =C21+J21-N21
A22: =DATE(2025,6,16) | B22: 16 | C22: =Q21 | J22: =SUM(D22:H22)+I22 | N22: =SUM(K22:M22) | P22: =00_PARAMETROS!B5 | Q22: =C22+J22-N22
A23: =DATE(2025,6,17) | B23: 17 | C23: =Q22 | J23: =SUM(D23:H23)+I23 | N23: =SUM(K23:M23) | P23: =00_PARAMETROS!B5 | Q23: =C23+J23-N23
A24: =DATE(2025,6,18) | B24: 18 | C24: =Q23 | J24: =SUM(D24:H24)+I24 | N24: =SUM(K24:M24) | P24: =00_PARAMETROS!B5 | Q24: =C24+J24-N24
A25: =DATE(2025,6,19) | B25: 19 | C25: =Q24 | J25: =SUM(D25:H25)+I25 | N25: =SUM(K25:M25) | P25: =00_PARAMETROS!B5 | Q25: =C25+J25-N25
A26: =DATE(2025,6,20) | B26: 20 | C26: =Q25 | J26: =SUM(D26:H26)+I26 | N26: =SUM(K26:M26) | P26: =00_PARAMETROS!B5 | Q26: =C26+J26-N26
A27: =DATE(2025,6,21) | B27: 21 | C27: =Q26 | J27: =SUM(D27:H27)+I27 | N27: =SUM(K27:M27) | P27: =00_PARAMETROS!B5 | Q27: =C27+J27-N27
A28: =DATE(2025,6,22) | B28: 22 | C28: =Q27 | J28: =SUM(D28:H28)+I28 | N28: =SUM(K28:M28) | P28: =00_PARAMETROS!B5 | Q28: =C28+J28-N28
A29: =DATE(2025,6,23) | B29: 23 | C29: =Q28 | J29: =SUM(D29:H29)+I29 | N29: =SUM(K29:M29) | P29: =00_PARAMETROS!B5 | Q29: =C29+J29-N29
A30: =DATE(2025,6,24) | B30: 24 | C30: =Q29 | J30: =SUM(D30:H30)+I30 | N30: =SUM(K30:M30) | P30: =00_PARAMETROS!B5 | Q30: =C30+J30-N30
A31: =DATE(2025,6,25) | B31: 25 | C31: =Q30 | J31: =SUM(D31:H31)+I31 | N31: =SUM(K31:M31) | P31: =00_PARAMETROS!B5 | Q31: =C31+J31-N31
A32: =DATE(2025,6,26) | B32: 26 | C32: =Q31 | J32: =SUM(D32:H32)+I32 | N32: =SUM(K32:M32) | P32: =00_PARAMETROS!B5 | Q32: =C32+J32-N32
A33: =DATE(2025,6,27) | B33: 27 | C33: =Q32 | J33: =SUM(D33:H33)+I33 | N33: =SUM(K33:M33) | P33: =00_PARAMETROS!B5 | Q33: =C33+J33-N33
A34: =DATE(2025,6,28) | B34: 28 | C34: =Q33 | J34: =SUM(D34:H34)+I34 | N34: =SUM(K34:M34) | P34: =00_PARAMETROS!B5 | Q34: =C34+J34-N34
A35: =DATE(2025,6,29) | B35: 29 | C35: =Q34 | J35: =SUM(D35:H35)+I35 | N35: =SUM(K35:M35) | P35: =00_PARAMETROS!B5 | Q35: =C35+J35-N35
A36: =DATE(2025,6,30) | B36: 30 | C36: =Q35 | J36: =SUM(D36:H36)+I36 | N36: =SUM(K36:M36) | P36: =00_PARAMETROS!B5 | Q36: =C36+J36-N36
A37: TOTAL | D37: =SUM(D7:D36) | E37: =SUM(E7:E36) | F37: =SUM(F7:F36) | G37: =SUM(G7:G36) | H37: =SUM(H7:H36) | I37: =SUM(I7:I36) | J37: =SUM(J7:J36) | K37: =SUM(K7:K36) | ... S37: =SUM(S7:S36)
A40: RESUMEN DEL MES
A41: Ingresos | B41: =J37
A42: Altas al hogar / otro hosp. | B42: =K37
...

Sheet JULIO 2025
A1: RESUMEN MENSUAL HODOM | U1: CONTROL
A2: Servicio | B2: =00_PARAMETROS!B3 | C2: Codigo | D2: =00_PARAMETROS!B4 | E2: Mes | F2: JULIO | G2: Ano | H2: 2025
A3: Camas base | B3: =00_PARAMETROS!B5 | C3: Promedio camas | D3: =AVERAGE(P7:P37) | E3: Dias del mes | F3: 31 | U3: Dias con ocupacion negativa | V3: =COUNTIF(Q7:Q37,"<0")
U4: Dias sin camas disponibles | V4: =COUNTBLANK(P7:P37)
U5: Primer dia sin existencia inicial | V5: =IF(C7="",1,0)
A6: Fecha | B6: Dia | C6: Existencia dia anterior | D6: Ing. urgencia | E6: Ing. hospitalizacion | F6: Ing. ambulatorio | G6: Ing. ley urgencia | H6: Ing. UGCC | I6: Ing. por traslado | J6: Total ingresos | K6: Egr. alta hogar / otro hosp. | L6: Egr. traslado a otro servicio | M6: Egr. fallecidos | N6: Total egresos | O6: Ingr.-egr. mismo dia | P6: Dias cama disponibles | Q6: Dias cama ocupadas | R6: Dias estada total | S6: Dias estada benef. | U6: Dias con total ingresos manualmente alterado | V6: 0
A7: =DATE(2025,7,1) | B7: 1 | J7: =SUM(D7:H7)+I7 | N7: =SUM(K7:M7) | P7: =00_PARAMETROS!B5 | Q7: =C7+J7-N7 | U7: Dias con total egresos manualmente alterado | V7: 0
A8: =DATE(2025,7,2) | B8: 2 | C8: =Q7 | J8: =SUM(D8:H8)+I8 | N8: =SUM(K8:M8) | P8: =00_PARAMETROS!B5 | Q8: =C8+J8-N8
A9: =DATE(2025,7,3) | B9: 3 | C9: =Q8 | J9: =SUM(D9:H9)+I9 | N9: =SUM(K9:M9) | P9: =00_PARAMETROS!B5 | Q9: =C9+J9-N9
A10: =DATE(2025,7,4) | B10: 4 | C10: =Q9 | J10: =SUM(D10:H10)+I10 | N10: =SUM(K10:M10) | P10: =00_PARAMETROS!B5 | Q10: =C10+J10-N10
A11: =DATE(2025,7,5) | B11: 5 | C11: =Q10 | J11: =SUM(D11:H11)+I11 | N11: =SUM(K11:M11) | P11: =00_PARAMETROS!B5 | Q11: =C11+J11-N11
A12: =DATE(2025,7,6) | B12: 6 | C12: =Q11 | J12: =SUM(D12:H12)+I12 | N12: =SUM(K12:M12) | P12: =00_PARAMETROS!B5 | Q12: =C12+J12-N12
A13: =DATE(2025,7,7) | B13: 7 | C13: =Q12 | J13: =SUM(D13:H13)+I13 | N13: =SUM(K13:M13) | P13: =00_PARAMETROS!B5 | Q13: =C13+J13-N13
A14: =DATE(2025,7,8) | B14: 8 | C14: =Q13 | J14: =SUM(D14:H14)+I14 | N14: =SUM(K14:M14) | P14: =00_PARAMETROS!B5 | Q14: =C14+J14-N14
A15: =DATE(2025,7,9) | B15: 9 | C15: =Q14 | J15: =SUM(D15:H15)+I15 | N15: =SUM(K15:M15) | P15: =00_PARAMETROS!B5 | Q15: =C15+J15-N15
A16: =DATE(2025,7,10) | B16: 10 | C16: =Q15 | J16: =SUM(D16:H16)+I16 | N16: =SUM(K16:M16) | P16: =00_PARAMETROS!B5 | Q16: =C16+J16-N16
A17: =DATE(2025,7,11) | B17: 11 | C17: =Q16 | J17: =SUM(D17:H17)+I17 | N17: =SUM(K17:M17) | P17: =00_PARAMETROS!B5 | Q17: =C17+J17-N17
A18: =DATE(2025,7,12) | B18: 12 | C18: =Q17 | J18: =SUM(D18:H18)+I18 | N18: =SUM(K18:M18) | P18: =00_PARAMETROS!B5 | Q18: =C18+J18-N18
A19: =DATE(2025,7,13) | B19: 13 | C19: =Q18 | J19: =SUM(D19:H19)+I19 | N19: =SUM(K19:M19) | P19: =00_PARAMETROS!B5 | Q19: =C19+J19-N19
A20: =DATE(2025,7,14) | B20: 14 | C20: =Q19 | J20: =SUM(D20:H20)+I20 | N20: =SUM(K20:M20) | P20: =00_PARAMETROS!B5 | Q20: =C20+J20-N20
A21: =DATE(2025,7,15) | B21: 15 | C21: =Q20 | J21: =SUM(D21:H21)+I21 | N21: =SUM(K21:M21) | P21: =00_PARAMETROS!B5 | Q21: =C21+J21-N21
A22: =DATE(2025,7,16) | B22: 16 | C22: =Q21 | J22: =SUM(D22:H22)+I22 | N22: =SUM(K22:M22) | P22: =00_PARAMETROS!B5 | Q22: =C22+J22-N22
A23: =DATE(2025,7,17) | B23: 17 | C23: =Q22 | J23: =SUM(D23:H23)+I23 | N23: =SUM(K23:M23) | P23: =00_PARAMETROS!B5 | Q23: =C23+J23-N23
A24: =DATE(2025,7,18) | B24: 18 | C24: =Q23 | J24: =SUM(D24:H24)+I24 | N24: =SUM(K24:M24) | P24: =00_PARAMETROS!B5 | Q24: =C24+J24-N24
A25: =DATE(2025,7,19) | B25: 19 | C25: =Q24 | J25: =SUM(D25:H25)+I25 | N25: =SUM(K25:M25) | P25: =00_PARAMETROS!B5 | Q25: =C25+J25-N25
A26: =DATE(2025,7,20) | B26: 20 | C26: =Q25 | J26: =SUM(D26:H26)+I26 | N26: =SUM(K26:M26) | P26: =00_PARAMETROS!B5 | Q26: =C26+J26-N26
A27: =DATE(2025,7,21) | B27: 21 | C27: =Q26 | J27: =SUM(D27:H27)+I27 | N27: =SUM(K27:M27) | P27: =00_PARAMETROS!B5 | Q27: =C27+J27-N27
A28: =DATE(2025,7,22) | B28: 22 | C28: =Q27 | J28: =SUM(D28:H28)+I28 | N28: =SUM(K28:M28) | P28: =00_PARAMETROS!B5 | Q28: =C28+J28-N28
A29: =DATE(2025,7,23) | B29: 23 | C29: =Q28 | J29: =SUM(D29:H29)+I29 | N29: =SUM(K29:M29) | P29: =00_PARAMETROS!B5 | Q29: =C29+J29-N29
A30: =DATE(2025,7,24) | B30: 24 | C30: =Q29 | J30: =SUM(D30:H30)+I30 | N30: =SUM(K30:M30) | P30: =00_PARAMETROS!B5 | Q30: =C30+J30-N30
A31: =DATE(2025,7,25) | B31: 25 | C31: =Q30 | J31: =SUM(D31:H31)+I31 | N31: =SUM(K31:M31) | P31: =00_PARAMETROS!B5 | Q31: =C31+J31-N31
A32: =DATE(2025,7,26) | B32: 26 | C32: =Q31 | J32: =SUM(D32:H32)+I32 | N32: =SUM(K32:M32) | P32: =00_PARAMETROS!B5 | Q32: =C32+J32-N32
A33: =DATE(2025,7,27) | B33: 27 | C33: =Q32 | J33: =SUM(D33:H33)+I33 | N33: =SUM(K33:M33) | P33: =00_PARAMETROS!B5 | Q33: =C33+J33-N33
A34: =DATE(2025,7,28) | B34: 28 | C34: =Q33 | J34: =SUM(D34:H34)+I34 | N34: =SUM(K34:M34) | P34: =00_PARAMETROS!B5 | Q34: =C34+J34-N34
A35: =DATE(2025,7,29) | B35: 29 | C35: =Q34 | J35: =SUM(D35:H35)+I35 | N35: =SUM(K35:M35) | P35: =00_PARAMETROS!B5 | Q35: =C35+J35-N35
A36: =DATE(2025,7,30) | B36: 30 | C36: =Q35 | J36: =SUM(D36:H36)+I36 | N36: =SUM(K36:M36) | P36: =00_PARAMETROS!B5 | Q36: =C36+J36-N36
A37: =DATE(2025,7,31) | B37: 31 | C37: =Q36 | J37: =SUM(D37:H37)+I37 | N37: =SUM(K37:M37) | P37: =00_PARAMETROS!B5 | Q37: =C37+J37-N37
A38: TOTAL | D38: =SUM(D7:D37) | E38: =SUM(E7:E37) | F38: =SUM(F7:F37) | G38: =SUM(G7:G37) | H38: =SUM(H7:H37) | I38: =SUM(I7:I37) | J38: =SUM(J7:J37) | K38: =SUM(K7:K37) | ... S38: =SUM(S7:S37)
A41: RESUMEN DEL MES
A42: Ingresos | B42: =J38
...

Sheet AGOSTO 2025
A1: RESUMEN MENSUAL HODOM | U1: CONTROL
A2: Servicio | B2: =00_PARAMETROS!B3 | C2: Codigo | D2: =00_PARAMETROS!B4 | E2: Mes | F2: AGOSTO | G2: Ano | H2: 2025
A3: Camas base | B3: =00_PARAMETROS!B5 | C3: Promedio camas | D3: =AVERAGE(P7:P37) | E3: Dias del mes | F3: 31 | U3: Dias con ocupacion negativa | V3: =COUNTIF(Q7:Q37,"<0")
U4: Dias sin camas disponibles | V4: =COUNTBLANK(P7:P37)
U5: Primer dia sin existencia inicial | V5: =IF(C7="",1,0)
A6: Fecha | B6: Dia | C6: Existencia dia anterior | D6: Ing. urgencia | E6: Ing. hospitalizacion | F6: Ing. ambulatorio | G6: Ing. ley urgencia | H6: Ing. UGCC | I6: Ing. por traslado | J6: Total ingresos | K6: Egr. alta hogar / otro hosp. | L6: Egr. traslado a otro servicio | M6: Egr. fallecidos | N6: Total egresos | O6: Ingr.-egr. mismo dia | P6: Dias cama disponibles | Q6: Dias cama ocupadas | R6: Dias estada total | S6: Dias estada benef. | U6: Dias con total ingresos manualmente alterado | V6: 0
A7: =DATE(2025,8,1) | B7: 1 | J7: =SUM(D7:H7)+I7 | N7: =SUM(K7:M7) | P7: =00_PARAMETROS!B5 | Q7: =C7+J7-N7 | U7: Dias con total egresos manualmente alterado | V7: 0
A8: =DATE(2025,8,2) | B8: 2 | C8: =Q7 | J8: =SUM(D8:H8)+I8 | N8: =SUM(K8:M8) | P8: =00_PARAMETROS!B5 | Q8: =C8+J8-N8
A9: =DATE(2025,8,3) | B9: 3 | C9: =Q8 | J9: =SUM(D9:H9)+I9 | N9: =SUM(K9:M9) | P9: =00_PARAMETROS!B5 | Q9: =C9+J9-N9
A10: =DATE(2025,8,4) | B10: 4 | C10: =Q9 | J10: =SUM(D10:H10)+I10 | N10: =SUM(K10:M10) | P10: =00_PARAMETROS!B5 | Q10: =C10+J10-N10
A11: =DATE(2025,8,5) | B11: 5 | C11: =Q10 | J11: =SUM(D11:H11)+I11 | N11: =SUM(K11:M11) | P11: =00_PARAMETROS!B5 | Q11: =C11+J11-N11
A12: =DATE(2025,8,6) | B12: 6 | C12: =Q11 | J12: =SUM(D12:H12)+I12 | N12: =SUM(K12:M12) | P12: =00_PARAMETROS!B5 | Q12: =C12+J12-N12
A13: =DATE(2025,8,7) | B13: 7 | C13: =Q12 | J13: =SUM(D13:H13)+I13 | N13: =SUM(K13:M13) | P13: =00_PARAMETROS!B5 | Q13: =C13+J13-N13
A14: =DATE(2025,8,8) | B14: 8 | C14: =Q13 | J14: =SUM(D14:H14)+I14 | N14: =SUM(K14:M14) | P14: =00_PARAMETROS!B5 | Q14: =C14+J14-N14
A15: =DATE(2025,8,9) | B15: 9 | C15: =Q14 | J15: =SUM(D15:H15)+I15 | N15: =SUM(K15:M15) | P15: =00_PARAMETROS!B5 | Q15: =C15+J15-N15
A16: =DATE(2025,8,10) | B16: 10 | C16: =Q15 | J16: =SUM(D16:H16)+I16 | N16: =SUM(K16:M16) | P16: =00_PARAMETROS!B5 | Q16: =C16+J16-N16
A17: =DATE(2025,8,11) | B17: 11 | C17: =Q16 | J17: =SUM(D17:H17)+I17 | N17: =SUM(K17:M17) | P17: =00_PARAMETROS!B5 | Q17: =C17+J17-N17
A18: =DATE(2025,8,12) | B18: 12 | C18: =Q17 | J18: =SUM(D18:H18)+I18 | N18: =SUM(K18:M18) | P18: =00_PARAMETROS!B5 | Q18: =C18+J18-N18
A19: =DATE(2025,8,13) | B19: 13 | C19: =Q18 | J19: =SUM(D19:H19)+I19 | N19: =SUM(K19:M19) | P19: =00_PARAMETROS!B5 | Q19: =C19+J19-N19
A20: =DATE(2025,8,14) | B20: 14 | C20: =Q19 | J20: =SUM(D20:H20)+I20 | N20: =SUM(K20:M20) | P20: =00_PARAMETROS!B5 | Q20: =C20+J20-N20
A21: =DATE(2025,8,15) | B21: 15 | C21: =Q20 | J21: =SUM(D21:H21)+I21 | N21: =SUM(K21:M21) | P21: =00_PARAMETROS!B5 | Q21: =C21+J21-N21
A22: =DATE(2025,8,16) | B22: 16 | C22: =Q21 | J22: =SUM(D22:H22)+I22 | N22: =SUM(K22:M22) | P22: =00_PARAMETROS!B5 | Q22: =C22+J22-N22
A23: =DATE(2025,8,17) | B23: 17 | C23: =Q22 | J23: =SUM(D23:H23)+I23 | N23: =SUM(K23:M23) | P23: =00_PARAMETROS!B5 | Q23: =C23+J23-N23
A24: =DATE(2025,8,18) | B24: 18 | C24: =Q23 | J24: =SUM(D24:H24)+I24 | N24: =SUM(K24:M24) | P24: =00_PARAMETROS!B5 | Q24: =C24+J24-N24
A25: =DATE(2025,8,19) | B25: 19 | C25: =Q24 | J25: =SUM(D25:H25)+I25 | N25: =SUM(K25:M25) | P25: =00_PARAMETROS!B5 | Q25: =C25+J25-N25
A26: =DATE(2025,8,20) | B26: 20 | C26: =Q25 | J26: =SUM(D26:H26)+I26 | N26: =SUM(K26:M26) | P26: =00_PARAMETROS!B5 | Q26: =C26+J26-N26
A27: =DATE(2025,8,21) | B27: 21 | C27: =Q26 | J27: =SUM(D27:H27)+I27 | N27: =SUM(K27:M27) | P27: =00_PARAMETROS!B5 | Q27: =C27+J27-N27
A28: =DATE(2025,8,22) | B28: 22 | C28: =Q27 | J28: =SUM(D28:H28)+I28 | N28: =SUM(K28:M28) | P28: =00_PARAMETROS!B5 | Q28: =C28+J28-N28
A29: =DATE(2025,8,23) | B29: 23 | C29: =Q28 | J29: =SUM(D29:H29)+I29 | N29: =SUM(K29:M29) | P29: =00_PARAMETROS!B5 | Q29: =C29+J29-N29
A30: =DATE(2025,8,24) | B30: 24 | C30: =Q29 | J30: =SUM(D30:H30)+I30 | N30: =SUM(K30:M30) | P30: =00_PARAMETROS!B5 | Q30: =C30+J30-N30
A31: =DATE(2025,8,25) | B31: 25 | C31: =Q30 | J31: =SUM(D31:H31)+I31 | N31: =SUM(K31:M31) | P31: =00_PARAMETROS!B5 | Q31: =C31+J31-N31
A32: =DATE(2025,8,26) | B32: 26 | C32: =Q31 | J32: =SUM(D32:H32)+I32 | N32: =SUM(K32:M32) | P32: =00_PARAMETROS!B5 | Q32: =C32+J32-N32
A33: =DATE(2025,8,27) | B33: 27 | C33: =Q32 | J33: =SUM(D33:H33)+I33 | N33: =SUM(K33:M33) | P33: =00_PARAMETROS!B5 | Q33: =C33+J33-N33
A34: =DATE(2025,8,28) | B34: 28 | C34: =Q33 | J34: =SUM(D34:H34)+I34 | N34: =SUM(K34:M34) | P34: =00_PARAMETROS!B5 | Q34: =C34+J34-N34
A35: =DATE(2025,8,29) | B35: 29 | C35: =Q34 | J35: =SUM(D35:H35)+I35 | N35: =SUM(K35:M35) | P35: =00_PARAMETROS!B5 | Q35: =C35+J35-N35
A36: =DATE(2025,8,30) | B36: 30 | C36: =Q35 | J36: =SUM(D36:H36)+I36 | N36: =SUM(K36:M36) | P36: =00_PARAMETROS!B5 | Q36: =C36+J36-N36
A37: =DATE(2025,8,31) | B37: 31 | C37: =Q36 | J37: =SUM(D37:H37)+I37 | N37: =SUM(K37:M37) | P37: =00_PARAMETROS!B5 | Q37: =C37+J37-N37
A38: TOTAL | D38: =SUM(D7:D37) | E38: =SUM(E7:E37) | F38: =SUM(F7:F37) | G38: =SUM(G7:G37) | H38: =SUM(H7:H37) | I38: =SUM(I7:I37) | J38: =SUM(J7:J37) | K38: =SUM(K7:K37) | ... S38: =SUM(S7:S37)
A41: RESUMEN DEL MES
A42: Ingresos | B42: =J38
...

Sheet SEPTIEMBRE 2025
A1: RESUMEN MENSUAL HODOM | U1: CONTROL
A2: Servicio | B2: =00_PARAMETROS!B3 | C2: Codigo | D2: =00_PARAMETROS!B4 | E2: Mes | F2: SEPTIEMBRE | G2: Ano | H2: 2025
A3: Camas base | B3: =00_PARAMETROS!B5 | C3: Promedio camas | D3: =AVERAGE(P7:P36) | E3: Dias del mes | F3: 30 | U3: Dias con ocupacion negativa | V3: =COUNTIF(Q7:Q36,"<0")
U4: Dias sin camas disponibles | V4: =COUNTBLANK(P7:P36)
U5: Primer dia sin existencia inicial | V5: =IF(C7="",1,0)
A6: Fecha | B6: Dia | C6: Existencia dia anterior | D6: Ing. urgencia | E6: Ing. hospitalizacion | F6: Ing. ambulatorio | G6: Ing. ley urgencia | H6: Ing. UGCC | I6: Ing. por traslado | J6: Total ingresos | K6: Egr. alta hogar / otro hosp. | L6: Egr. traslado a otro servicio | M6: Egr. fallecidos | N6: Total egresos | O6: Ingr.-egr. mismo dia | P6: Dias cama disponibles | Q6: Dias cama ocupadas | R6: Dias estada total | S6: Dias estada benef. | U6: Dias con total ingresos manualmente alterado | V6: 0
A7: =DATE(2025,9,1) | B7: 1 | J7: =SUM(D7:H7)+I7 | N7: =SUM(K7:M7) | P7: =00_PARAMETROS!B5 | Q7: =C7+J7-N7 | U7: Dias con total egresos manualmente alterado | V7: 0
A8: =DATE(2025,9,2) | B8: 2 | C8: =Q7 | J8: =SUM(D8:H8)+I8 | N8: =SUM(K8:M8) | P8: =00_PARAMETROS!B5 | Q8: =C8+J8-N8
A9: =DATE(2025,9,3) | B9: 3 | C9: =Q8 | J9: =SUM(D9:H9)+I9 | N9: =SUM(K9:M9) | P9: =00_PARAMETROS!B5 | Q9: =C9+J9-N9
A10: =DATE(2025,9,4) | B10: 4 | C10: =Q9 | J10: =SUM(D10:H10)+I10 | N10: =SUM(K10:M10) | P10: =00_PARAMETROS!B5 | Q10: =C10+J10-N10
A11: =DATE(2025,9,5) | B11: 5 | C11: =Q10 | J11: =SUM(D11:H11)+I11 | N11: =SUM(K11:M11) | P11: =00_PARAMETROS!B5 | Q11: =C11+J11-N11
A12: =DATE(2025,9,6) | B12: 6 | C12: =Q11 | J12: =SUM(D12:H12)+I12 | N12: =SUM(K12:M12) | P12: =00_PARAMETROS!B5 | Q12: =C12+J12-N12
A13: =DATE(2025,9,7) | B13: 7 | C13: =Q12 | J13: =SUM(D13:H13)+I13 | N13: =SUM(K13:M13) | P13: =00_PARAMETROS!B5 | Q13: =C13+J13-N13
A14: =DATE(2025,9,8) | B14: 8 | C14: =Q13 | J14: =SUM(D14:H14)+I14 | N14: =SUM(K14:M14) | P14: =00_PARAMETROS!B5 | Q14: =C14+J14-N14
A15: =DATE(2025,9,9) | B15: 9 | C15: =Q14 | J15: =SUM(D15:H15)+I15 | N15: =SUM(K15:M15) | P15: =00_PARAMETROS!B5 | Q15: =C15+J15-N15
A16: =DATE(2025,9,10) | B16: 10 | C16: =Q15 | J16: =SUM(D16:H16)+I16 | N16: =SUM(K16:M16) | P16: =00_PARAMETROS!B5 | Q16: =C16+J16-N16
A17: =DATE(2025,9,11) | B17: 11 | C17: =Q16 | J17: =SUM(D17:H17)+I17 | N17: =SUM(K17:M17) | P17: =00_PARAMETROS!B5 | Q17: =C17+J17-N17
A18: =DATE(2025,9,12) | B18: 12 | C18: =Q17 | J18: =SUM(D18:H18)+I18 | N18: =SUM(K18:M18) | P18: =00_PARAMETROS!B5 | Q18: =C18+J18-N18
A19: =DATE(2025,9,13) | B19: 13 | C19: =Q18 | J19: =SUM(D19:H19)+I19 | N19: =SUM(K19:M19) | P19: =00_PARAMETROS!B5 | Q19: =C19+J19-N19
A20: =DATE(2025,9,14) | B20: 14 | C20: =Q19 | J20: =SUM(D20:H20)+I20 | N20: =SUM(K20:M20) | P20: =00_PARAMETROS!B5 | Q20: =C20+J20-N20
A21: =DATE(2025,9,15) | B21: 15 | C21: =Q20 | J21: =SUM(D21:H21)+I21 | N21: =SUM(K21:M21) | P21: =00_PARAMETROS!B5 | Q21: =C21+J21-N21
A22: =DATE(2025,9,16) | B22: 16 | C22: =Q21 | J22: =SUM(D22:H22)+I22 | N22: =SUM(K22:M22) | P22: =00_PARAMETROS!B5 | Q22: =C22+J22-N22
A23: =DATE(2025,9,17) | B23: 17 | C23: =Q22 | J23: =SUM(D23:H23)+I23 | N23: =SUM(K23:M23) | P23: =00_PARAMETROS!B5 | Q23: =C23+J23-N23
A24: =DATE(2025,9,18) | B24: 18 | C24: =Q23 | J24: =SUM(D24:H24)+I24 | N24: =SUM(K24:M24) | P24: =00_PARAMETROS!B5 | Q24: =C24+J24-N24
A25: =DATE(2025,9,19) | B25: 19 | C25: =Q24 | J25: =SUM(D25:H25)+I25 | N25: =SUM(K25:M25) | P25: =00_PARAMETROS!B5 | Q25: =C25+J25-N25
A26: =DATE(2025,9,20) | B26: 20 | C26: =Q25 | J26: =SUM(D26:H26)+I26 | N26: =SUM(K26:M26) | P26: =00_PARAMETROS!B5 | Q26: =C26+J26-N26
A27: =DATE(2025,9,21) | B27: 21 | C27: =Q26 | J27: =SUM(D27:H27)+I27 | N27: =SUM(K27:M27) | P27: =00_PARAMETROS!B5 | Q27: =C27+J27-N27
A28: =DATE(2025,9,22) | B28: 22 | C28: =Q27 | J28: =SUM(D28:H28)+I28 | N28: =SUM(K28:M28) | P28: =00_PARAMETROS!B5 | Q28: =C28+J28-N28
A29: =DATE(2025,9,23) | B29: 23 | C29: =Q28 | J29: =SUM(D29:H29)+I29 | N29: =SUM(K29:M29) | P29: =00_PARAMETROS!B5 | Q29: =C29+J29-N29
A30: =DATE(2025,9,24) | B30: 24 | C30: =Q29 | J30: =SUM(D30:H30)+I30 | N30: =SUM(K30:M30) | P30: =00_PARAMETROS!B5 | Q30: =C30+J30-N30
A31: =DATE(2025,9,25) | B31: 25 | C31: =Q30 | J31: =SUM(D31:H31)+I31 | N31: =SUM(K31:M31) | P31: =00_PARAMETROS!B5 | Q31: =C31+J31-N31
A32: =DATE(2025,9,26) | B32: 26 | C32: =Q31 | J32: =SUM(D32:H32)+I32 | N32: =SUM(K32:M32) | P32: =00_PARAMETROS!B5 | Q32: =C32+J32-N32
A33: =DATE(2025,9,27) | B33: 27 | C33: =Q32 | J33: =SUM(D33:H33)+I33 | N33: =SUM(K33:M33) | P33: =00_PARAMETROS!B5 | Q33: =C33+J33-N33
A34: =DATE(2025,9,28) | B34: 28 | C34: =Q33 | J34: =SUM(D34:H34)+I34 | N34: =SUM(K34:M34) | P34: =00_PARAMETROS!B5 | Q34: =C34+J34-N34
A35: =DATE(2025,9,29) | B35: 29 | C35: =Q34 | J35: =SUM(D35:H35)+I35 | N35: =SUM(K35:M35) | P35: =00_PARAMETROS!B5 | Q35: =C35+J35-N35
A36: =DATE(2025,9,30) | B36: 30 | C36: =Q35 | J36: =SUM(D36:H36)+I36 | N36: =SUM(K36:M36) | P36: =00_PARAMETROS!B5 | Q36: =C36+J36-N36
A37: TOTAL | D37: =SUM(D7:D36) | E37: =SUM(E7:E36) | F37: =SUM(F7:F36) | G37: =SUM(G7:G36) | H37: =SUM(H7:H36) | I37: =SUM(I7:I36) | J37: =SUM(J7:J36) | K37: =SUM(K7:K36) | ... S37: =SUM(S7:S36)
A40: RESUMEN DEL MES
A41: Ingresos | B41: =J37
A42: Altas al hogar / otro hosp. | B42: =K37
...

Sheet OCTUBRE 2025
A1: RESUMEN MENSUAL HODOM | U1: CONTROL
A2: Servicio | B2: =00_PARAMETROS!B3 | C2: Codigo | D2: =00_PARAMETROS!B4 | E2: Mes | F2: OCTUBRE | G2: Ano | H2: 2025
A3: Camas base | B3: =00_PARAMETROS!B5 | C3: Promedio camas | D3: =AVERAGE(P7:P37) | E3: Dias del mes | F3: 31 | U3: Dias con ocupacion negativa | V3: =COUNTIF(Q7:Q37,"<0")
U4: Dias sin camas disponibles | V4: =COUNTBLANK(P7:P37)
U5: Primer dia sin existencia inicial | V5: =IF(C7="",1,0)
A6: Fecha | B6: Dia | C6: Existencia dia anterior | D6: Ing. urgencia | E6: Ing. hospitalizacion | F6: Ing. ambulatorio | G6: Ing. ley urgencia | H6: Ing. UGCC | I6: Ing. por traslado | J6: Total ingresos | K6: Egr. alta hogar / otro hosp. | L6: Egr. traslado a otro servicio | M6: Egr. fallecidos | N6: Total egresos | O6: Ingr.-egr. mismo dia | P6: Dias cama disponibles | Q6: Dias cama ocupadas | R6: Dias estada total | S6: Dias estada benef. | U6: Dias con total ingresos manualmente alterado | V6: 0
A7: =DATE(2025,10,1) | B7: 1 | J7: =SUM(D7:H7)+I7 | N7: =SUM(K7:M7) | P7: =00_PARAMETROS!B5 | Q7: =C7+J7-N7 | U7: Dias con total egresos manualmente alterado | V7: 0
A8: =DATE(2025,10,2) | B8: 2 | C8: =Q7 | J8: =SUM(D8:H8)+I8 | N8: =SUM(K8:M8) | P8: =00_PARAMETROS!B5 | Q8: =C8+J8-N8
A9: =DATE(2025,10,3) | B9: 3 | C9: =Q8 | J9: =SUM(D9:H9)+I9 | N9: =SUM(K9:M9) | P9: =00_PARAMETROS!B5 | Q9: =C9+J9-N9
A10: =DATE(2025,10,4) | B10: 4 | C10: =Q9 | J10: =SUM(D10:H10)+I10 | N10: =SUM(K10:M10) | P10: =00_PARAMETROS!B5 | Q10: =C10+J10-N10
A11: =DATE(2025,10,5) | B11: 5 | C11: =Q10 | J11: =SUM(D11:H11)+I11 | N11: =SUM(K11:M11) | P11: =00_PARAMETROS!B5 | Q11: =C11+J11-N11
A12: =DATE(2025,10,6) | B12: 6 | C12: =Q11 | J12: =SUM(D12:H12)+I12 | N12: =SUM(K12:M12) | P12: =00_PARAMETROS!B5 | Q12: =C12+J12-N12
A13: =DATE(2025,10,7) | B13: 7 | C13: =Q12 | J13: =SUM(D13:H13)+I13 | N13: =SUM(K13:M13) | P13: =00_PARAMETROS!B5 | Q13: =C13+J13-N13
A14: =DATE(2025,10,8) | B14: 8 | C14: =Q13 | J14: =SUM(D14:H14)+I14 | N14: =SUM(K14:M14) | P14: =00_PARAMETROS!B5 | Q14: =C14+J14-N14
A15: =DATE(2025,10,9) | B15: 9 | C15: =Q14 | J15: =SUM(D15:H15)+I15 | N15: =SUM(K15:M15) | P15: =00_PARAMETROS!B5 | Q15: =C15+J15-N15
A16: =DATE(2025,10,10) | B16: 10 | C16: =Q15 | J16: =SUM(D16:H16)+I16 | N16: =SUM(K16:M16) | P16: =00_PARAMETROS!B5 | Q16: =C16+J16-N16
A17: =DATE(2025,10,11) | B17: 11 | C17: =Q16 | J17: =SUM(D17:H17)+I17 | N17: =SUM(K17:M17) | P17: =00_PARAMETROS!B5 | Q17: =C17+J17-N17
A18: =DATE(2025,10,12) | B18: 12 | C18: =Q17 | J18: =SUM(D18:H18)+I18 | N18: =SUM(K18:M18) | P18: =00_PARAMETROS!B5 | Q18: =C18+J18-N18
A19: =DATE(2025,10,13) | B19: 13 | C19: =Q18 | J19: =SUM(D19:H19)+I19 | N19: =SUM(K19:M19) | P19: =00_PARAMETROS!B5 | Q19: =C19+J19-N19
A20: =DATE(2025,10,14) | B20: 14 | C20: =Q19 | J20: =SUM(D20:H20)+I20 | N20: =SUM(K20:M20) | P20: =00_PARAMETROS!B5 | Q20: =C20+J20-N20
A21: =DATE(2025,10,15) | B21: 15 | C21: =Q20 | J21: =SUM(D21:H21)+I21 | N21: =SUM(K21:M21) | P21: =00_PARAMETROS!B5 | Q21: =C21+J21-N21
A22: =DATE(2025,10,16) | B22: 16 | C22: =Q21 | J22: =SUM(D22:H22)+I22 | N22: =SUM(K22:M22) | P22: =00_PARAMETROS!B5 | Q22: =C22+J22-N22
A23: =DATE(2025,10,17) | B23: 17 | C23: =Q22 | J23: =SUM(D23:H23)+I23 | N23: =SUM(K23:M23) | P23: =00_PARAMETROS!B5 | Q23: =C23+J23-N23
A24: =DATE(2025,10,18) | B24: 18 | C24: =Q23 | J24: =SUM(D24:H24)+I24 | N24: =SUM(K24:M24) | P24: =00_PARAMETROS!B5 | Q24: =C24+J24-N24
A25: =DATE(2025,10,19) | B25: 19 | C25: =Q24 | J25: =SUM(D25:H25)+I25 | N25: =SUM(K25:M25) | P25: =00_PARAMETROS!B5 | Q25: =C25+J25-N25
A26: =DATE(2025,10,20) | B26: 20 | C26: =Q25 | J26: =SUM(D26:H26)+I26 | N26: =SUM(K26:M26) | P26: =00_PARAMETROS!B5 | Q26: =C26+J26-N26
A27: =DATE(2025,10,21) | B27: 21 | C27: =Q26 | J27: =SUM(D27:H27)+I27 | N27: =SUM(K27:M27) | P27: =00_PARAMETROS!B5 | Q27: =C27+J27-N27
A28: =DATE(2025,10,22) | B28: 22 | C28: =Q27 | J28: =SUM(D28:H28)+I28 | N28: =SUM(K28:M28) | P28: =00_PARAMETROS!B5 | Q28: =C28+J28-N28
A29: =DATE(2025,10,23) | B29: 23 | C29: =Q28 | J29: =SUM(D29:H29)+I29 | N29: =SUM(K29:M29) | P29: =00_PARAMETROS!B5 | Q29: =C29+J29-N29
A30: =DATE(2025,10,24) | B30: 24 | C30: =Q29 | J30: =SUM(D30:H30)+I30 | N30: =SUM(K30:M30) | P30: =00_PARAMETROS!B5 | Q30: =C30+J30-N30
A31: =DATE(2025,10,25) | B31: 25 | C31: =Q30 | J31: =SUM(D31:H31)+I31 | N31: =SUM(K31:M31) | P31: =00_PARAMETROS!B5 | Q31: =C31+J31-N31
A32: =DATE(2025,10,26) | B32: 26 | C32: =Q31 | J32: =SUM(D32:H32)+I32 | N32: =SUM(K32:M32) | P32: =00_PARAMETROS!B5 | Q32: =C32+J32-N32
A33: =DATE(2025,10,27) | B33: 27 | C33: =Q32 | J33: =SUM(D33:H33)+I33 | N33: =SUM(K33:M33) | P33: =00_PARAMETROS!B5 | Q33: =C33+J33-N33
A34: =DATE(2025,10,28) | B34: 28 | C34: =Q33 | J34: =SUM(D34:H34)+I34 | N34: =SUM(K34:M34) | P34: =00_PARAMETROS!B5 | Q34: =C34+J34-N34
A35: =DATE(2025,10,29) | B35: 29 | C35: =Q34 | J35: =SUM(D35:H35)+I35 | N35: =SUM(K35:M35) | P35: =00_PARAMETROS!B5 | Q35: =C35+J35-N35
A36: =DATE(2025,10,30) | B36: 30 | C36: =Q35 | J36: =SUM(D36:H36)+I36 | N36: =SUM(K36:M36) | P36: =00_PARAMETROS!B5 | Q36: =C36+J36-N36
A37: =DATE(2025,10,31) | B37: 31 | C37: =Q36 | J37: =SUM(D37:H37)+I37 | N37: =SUM(K37:M37) | P37: =00_PARAMETROS!B5 | Q37: =C37+J37-N37
A38: TOTAL | D38: =SUM(D7:D37) | E38: =SUM(E7:E37) | F38: =SUM(F7:F37) | G38: =SUM(G7:G37) | H38: =SUM(H7:H37) | I38: =SUM(I7:I37) | J38: =SUM(J7:J37) | K38: =SUM(K7:K37) | ... S38: =SUM(S7:S37)
A41: RESUMEN DEL MES
A42: Ingresos | B42: =J38
...

Sheet NOVIEMBRE 2025
A1: RESUMEN MENSUAL HODOM | U1: CONTROL
A2: Servicio | B2: =00_PARAMETROS!B3 | C2: Codigo | D2: =00_PARAMETROS!B4 | E2: Mes | F2: NOVIEMBRE | G2: Ano | H2: 2025
A3: Camas base | B3: =00_PARAMETROS!B5 | C3: Promedio camas | D3: =AVERAGE(P7:P36) | E3: Dias del mes | F3: 30 | U3: Dias con ocupacion negativa | V3: =COUNTIF(Q7:Q36,"<0")
U4: Dias sin camas disponibles | V4: =COUNTBLANK(P7:P36)
